Workbook

Sheet Pairings NB
B1: Conexión > o = a 50min y < a 1hr y 30min | E1: NO CONSIDERAR TRU/JUL/JAE/AYP/JAU/IQT | J1: CONSIDERAR PAIRINGS PARTIDOS LCK A320 | O1: Vuelos LCK = Siempre en Flota 320
B2: Vuelos HBT mayor a 1 hora | E2: PSV NO MAYOR A 11 HRS | J2: CONSIDERAR SIEMPRE EL PDR | O2: Vuelos iniciando más de 08:30
E3: NO REPETIR PAIRING EN LCK
Q6: Pairing ID | R6: Fecha | S6: DíaSem | T6: Vuelo | U6: Ruta | V6: Instructor | W6: Actividad | X6: Sub Flota
B8: Pairing ID | C8: FECHA REAL | D8: Day of Week | E8: Flight No | F8: Dep Stn | G8: Arr Stn | H8: STD | I8: STA | J8: subflota | K8: Conexion | L8: HBT
B9: 113 | C9: 01/10/2026 | D9: jueves | E9: 2007 | F9: LIM | G9: CUZ | H9: 09:10:00 | I9: 10:30:00 | J9: 320 | L9: 01:20:00 | Q9: =B9 -> 113 | R9: =C9 -> 01/10/2026 | S9: =D9 -> jueves | T9: =E9&"/"&E10 -> 2007/2008 | U9: =F9&"-"&G9&"-"&F9 -> LIM-CUZ-LIM | V9: =IF($M$9="","",$M$9) | W9: =IF($O$9="","",$O$9) | X9: =J9 -> 320
B10: 113 | C10: 01/10/2026 | D10: jueves | E10: 2008 | F10: CUZ | G10: LIM | H10: 11:20:00 | I10: 12:55:00 | J10: 320 | K10: =TEXT(TIMEVALUE(H10)-TIMEVALUE(I9)+(TIMEVALUE(H10)<TIMEVALUE(I9)),"[h]:mm") -> 0:50 | L10: 01:35:00 | O10: ="LIM-"&G9&"-LIM LA "&E9&" ("&LEFT(H9,5)&"-"&LEFT(I9,5)&" hrs) / LA "&E10&" ("&LEFT(H10,5)&"-"&LEFT(I10,5)&" hrs)" -> LIM-CUZ-LIM LA 2007 (09:10-10:30 hrs) / LA 2008 (11:20-12:55 hrs)
B11: 135 | C11: 01/10/2026 | D11: jueves | E11: 2152 | F11: LIM | G11: CIX | H11: 13:50:00 | I11: 15:20:00 | J11: 320 | K11: =TEXT(TIMEVALUE(H11)-TIMEVALUE(I10)+(TIMEVALUE(H11)<TIMEVALUE(I10)),"[h]:mm") -> 0:55 | L11: 01:30:00 | M11: =IF($M$9="","",$M$9) | O11: =IF($O$9="","",$O$9) | Q11: =B11 -> 135 | R11: =C11 -> 01/10/2026 | S11: =D11 -> jueves | T11: =E11&"/"&E12 -> 2152/2153 | U11: =F11&"-"&G11&"-"&F11 -> LIM-CIX-LIM | V11: =IF($M$9="","",$M$9) | W11: =IF($O$9="","",$O$9) | X11: =J11 -> 320
B12: 135 | C12: 01/10/2026 | D12: jueves | E12: 2153 | F12: CIX | G12: LIM | H12: 15:55:00 | I12: 17:15:00 | J12: 320 | K12: =TEXT(TIMEVALUE(H12)-TIMEVALUE(I11)+(TIMEVALUE(H12)<TIMEVALUE(I11)),"[h]:mm") -> 0:35 | L12: 01:20:00 | O12: ="LIM-"&G11&"-LIM LA "&E11&" ("&LEFT(H11,5)&"-"&LEFT(I11,5)&" hrs) / LA "&E12&" ("&LEFT(H12,5)&"-"&LEFT(I12,5)&" hrs)" -> LIM-CIX-LIM LA 2152 (13:50-15:20 hrs) / LA 2153 (15:55-17:15 hrs)
J13: PSV total: | K13: =TEXT(TIMEVALUE(I12)-TIMEVALUE(H9)+(I12<H9),"[h]:mm") -> 8:05
B15: Pairing ID | C15: FECHA REAL | D15: Day of Week | E15: Flight No | F15: Dep Stn | G15: Arr Stn | H15: STD | I15: STA | J15: subflota | K15: Conexion | L15: HBT
B16: 117 | C16: 01/10/2026 | D16: jueves | E16: 2260 | F16: LIM | G16: PEM | H16: 10:20:00 | I16: 12:05:00 | J16: 320 | L16: 01:45:00 | Q16: =B16 -> 117 | R16: =C16 -> 01/10/2026 | S16: =D16 -> jueves | T16: =E16&"/"&E17 -> 2260/2261 | U16: =F16&"-"&G16&"-"&F16 -> LIM-PEM-LIM | V16: =IF($M$16="","",$M$16) | W16: =IF($O$16="","",$O$16) | X16: =J16 -> 320
B17: 117 | C17: 01/10/2026 | D17: jueves | E17: 2261 | F17: PEM | G17: LIM | H17: 12:45:00 | I17: 14:20:00 | J17: 320 | K17: =TEXT(TIMEVALUE(H17)-TIMEVALUE(I16)+(TIMEVALUE(H17)<TIMEVALUE(I16)),"[h]:mm") -> 0:40 | L17: 01:35:00 | O17: ="LIM-"&G16&"-LIM LA "&E16&" ("&LEFT(H16,5)&"-"&LEFT(I16,5)&" hrs) / LA "&E17&" ("&LEFT(H17,5)&"-"&LEFT(I17,5)&" hrs)" -> LIM-PEM-LIM LA 2260 (10:20-12:05 hrs) / LA 2261 (12:45-14:20 hrs)
B18: 144 | C18: 01/10/2026 | D18: jueves | E18: 2297 | F18: LIM | G18: CJA | H18: 15:15:00 | I18: 16:35:00 | J18: 320 | K18: =TEXT(TIMEVALUE(H18)-TIMEVALUE(I17)+(TIMEVALUE(H18)<TIMEVALUE(I17)),"[h]:mm") -> 0:55 | L18: 01:20:00 | M18: =IF($M$16="","",$M$16) | O18: =IF($O$16="","",$O$16) | Q18: =B18 -> 144 | R18: =C18 -> 01/10/2026 | S18: =D18 -> jueves | T18: =E18&"/"&E19 -> 2297/2296 | U18: =F18&"-"&G18&"-"&F18 -> LIM-CJA-LIM | V18: =IF($M$16="","",$M$16) | W18: =IF($O$16="","",$O$16) | X18: =J18 -> 320
B19: 144 | C19: 01/10/2026 | D19: jueves | E19: 2296 | F19: CJA | G19: LIM | H19: 17:20:00 | I19: 18:25:00 | J19: 320 | K19: =TEXT(TIMEVALUE(H19)-TIMEVALUE(I18)+(TIMEVALUE(H19)<TIMEVALUE(I18)),"[h]:mm") -> 0:45 | L19: 01:05:00 | O19: ="LIM-"&G18&"-LIM LA "&E18&" ("&LEFT(H18,5)&"-"&LEFT(I18,5)&" hrs) / LA "&E19&" ("&LEFT(H19,5)&"-"&LEFT(I19,5)&" hrs)" -> LIM-CJA-LIM LA 2297 (15:15-16:35 hrs) / LA 2296 (17:20-18:25 hrs)
J20: PSV total: | K20: =TEXT(TIMEVALUE(I19)-TIMEVALUE(H16)+(I19<H16),"[h]:mm") -> 8:05
B22: Pairing ID | C22: FECHA REAL | D22: Day of Week | E22: Flight No | F22: Dep Stn | G22: Arr Stn | H22: STD | I22: STA | J22: subflota | K22: Conexion | L22: HBT
B23: 118 | C23: 01/10/2026 | D23: jueves | E23: 2109 | F23: LIM | G23: AQP | H23: 10:30:00 | I23: 12:00:00 | J23: 320 | L23: 01:30:00 | Q23: =B23 -> 118 | R23: =C23 -> 01/10/2026 | S23: =D23 -> jueves | T23: =E23&"/"&E24 -> 2109/2108 | U23: =F23&"-"&G23&"-"&F23 -> LIM-AQP-LIM | V23: =IF($M$23="","",$M$23) | W23: =IF($O$23="","",$O$23) | X23: =J23 -> 320
B24: 118 | C24: 01/10/2026 | D24: jueves | E24: 2108 | F24: AQP | G24: LIM | H24: 12:45:00 | I24: 14:20:00 | J24: 320 | K24: =TEXT(TIMEVALUE(H24)-TIMEVALUE(I23)+(TIMEVALUE(H24)<TIMEVALUE(I23)),"[h]:mm") -> 0:45 | L24: 01:35:00 | O24: ="LIM-"&G23&"-LIM LA "&E23&" ("&LEFT(H23,5)&"-"&LEFT(I23,5)&" hrs) / LA "&E24&" ("&LEFT(H24,5)&"-"&LEFT(I24,5)&" hrs)" -> LIM-AQP-LIM LA 2109 (10:30-12:00 hrs) / LA 2108 (12:45-14:20 hrs)
B25: 145 | C25: 01/10/2026 | D25: jueves | E25: 2360 | F25: LIM | G25: PCL | H25: 15:25:00 | I25: 16:40:00 | J25: 319 | K25: =TEXT(TIMEVALUE(H25)-TIMEVALUE(I24)+(TIMEVALUE(H25)<TIMEVALUE(I24)),"[h]:mm") -> 1:05 | L25: 01:15:00 | M25: =IF($M$23="","",$M$23) | O25: =IF($O$23="","",$O$23) | Q25: =B25 -> 145 | R25: =C25 -> 01/10/2026 | S25: =D25 -> jueves | T25: =E25&"/"&E26 -> 2360/2361 | U25: =F25&"-"&G25&"-"&F25 -> LIM-PCL-LIM | V25: =IF($M$23="","",$M$23) | W25: =IF($O$23="","",$O$23) | X25: =J25 -> 319
B26: 145 | C26: 01/10/2026 | D26: jueves | E26: 2361 | F26: PCL | G26: LIM | H26: 17:20:00 | I26: 18:35:00 | J26: 319 | K26: =TEXT(TIMEVALUE(H26)-TIMEVALUE(I25)+(TIMEVALUE(H26)<TIMEVALUE(I25)),"[h]:mm") -> 0:40 | L26: 01:15:00 | O26: ="LIM-"&G25&"-LIM LA "&E25&" ("&LEFT(H25,5)&"-"&LEFT(I25,5)&" hrs) / LA "&E26&" ("&LEFT(H26,5)&"-"&LEFT(I26,5)&" hrs)" -> LIM-PCL-LIM LA 2360 (15:25-16:40 hrs) / LA 2361 (17:20-18:35 hrs)
J27: PSV total: | K27: =TEXT(TIMEVALUE(I26)-TIMEVALUE(H23)+(I26<H23),"[h]:mm") -> 8:05
B29: Pairing ID | C29: FECHA REAL | D29: Day of Week | E29: Flight No | F29: Dep Stn | G29: Arr Stn | H29: STD | I29: STA | J29: subflota | K29: Conexion | L29: HBT
B30: 119 | C30: 01/10/2026 | D30: jueves | E30: 2019 | F30: LIM | G30: IQT | H30: 11:35:00 | I30: 13:25:00 | J30: 319 | L30: 01:50:00 | Q30: =B30 -> 119 | R30: =C30 -> 01/10/2026 | S30: =D30 -> jueves | T30: =E30&"/"&E31 -> 2019/2038 | U30: =F30&"-"&G30&"-"&F30 -> LIM-IQT-LIM | V30: =IF($M$30="","",$M$30) | W30: =IF($O$30="","",$O$30) | X30: =J30 -> 319
B31: 119 | C31: 01/10/2026 | D31: jueves | E31: 2038 | F31: IQT | G31: LIM | H31: 14:05:00 | I31: 15:55:00 | J31: 319 | K31: =TEXT(TIMEVALUE(H31)-TIMEVALUE(I30)+(TIMEVALUE(H31)<TIMEVALUE(I30)),"[h]:mm") -> 0:40 | L31: 01:50:00 | O31: ="LIM-"&G30&"-LIM LA "&E30&" ("&LEFT(H30,5)&"-"&LEFT(I30,5)&" hrs) / LA "&E31&" ("&LEFT(H31,5)&"-"&LEFT(I31,5)&" hrs)" -> LIM-IQT-LIM LA 2019 (11:35-13:25 hrs) / LA 2038 (14:05-15:55 hrs)
B32: 151 | C32: 01/10/2026 | D32: jueves | E32: 2115 | F32: LIM | G32: AQP | H32: 17:15:00 | I32: 18:45:00 | J32: 320 | K32: =TEXT(TIMEVALUE(H32)-TIMEVALUE(I31)+(TIMEVALUE(H32)<TIMEVALUE(I31)),"[h]:mm") -> 1:20 | L32: 01:30:00 | M32: =IF($M$30="","",$M$30) | O32: =IF($O$30="","",$O$30) | Q32: =B32 -> 151 | R32: =C32 -> 01/10/2026 | S32: =D32 -> jueves | T32: =E32&"/"&E33 -> 2115/2114 | U32: =F32&"-"&G32&"-"&F32 -> LIM-AQP-LIM | V32: =IF($M$30="","",$M$30) | W32: =IF($O$30="","",$O$30) | X32: =J32 -> 320
B33: 151 | C33: 01/10/2026 | D33: jueves | E33: 2114 | F33: AQP | G33: LIM | H33: 19:20:00 | I33: 21:00:00 | J33: 320 | K33: =TEXT(TIMEVALUE(H33)-TIMEVALUE(I32)+(TIMEVALUE(H33)<TIMEVALUE(I32)),"[h]:mm") -> 0:35 | L33: 01:40:00 | O33: ="LIM-"&G32&"-LIM LA "&E32&" ("&LEFT(H32,5)&"-"&LEFT(I32,5)&" hrs) / LA "&E33&" ("&LEFT(H33,5)&"-"&LEFT(I33,5)&" hrs)" -> LIM-AQP-LIM LA 2115 (17:15-18:45 hrs) / LA 2114 (19:20-21:00 hrs)
J34: PSV total: | K34: =TEXT(TIMEVALUE(I33)-TIMEVALUE(H30)+(I33<H30),"[h]:mm") -> 9:25
B36: Pairing ID | C36: FECHA REAL | D36: Day of Week | E36: Flight No | F36: Dep Stn | G36: Arr Stn | H36: STD | I36: STA | J36: subflota | K36: Conexion | L36: HBT
B37: 120 | C37: 01/10/2026 | D37: jueves | E37: 2299 | F37: LIM | G37: CJA | H37: 11:35:00 | I37: 12:55:00 | J37: 320 | L37: 01:20:00 | Q37: =B37 -> 120 | R37: =C37 -> 01/10/2026 | S37: =D37 -> jueves | T37: =E37&"/"&E38 -> 2299/2298 | U37: =F37&"-"&G37&"-"&F37 -> LIM-CJA-LIM | V37: =IF($M$37="","",$M$37) | W37: =IF($O$37="","",$O$37) | X37: =J37 -> 320
B38: 120 | C38: 01/10/2026 | D38: jueves | E38: 2298 | F38: CJA | G38: LIM | H38: 13:40:00 | I38: 14:50:00 | J38: 320 | K38: =TEXT(TIMEVALUE(H38)-TIMEVALUE(I37)+(TIMEVALUE(H38)<TIMEVALUE(I37)),"[h]:mm") -> 0:45 | L38: 01:10:00 | O38: ="LIM-"&G37&"-LIM LA "&E37&" ("&LEFT(H37,5)&"-"&LEFT(I37,5)&" hrs) / LA "&E38&" ("&LEFT(H38,5)&"-"&LEFT(I38,5)&" hrs)" -> LIM-CJA-LIM LA 2299 (11:35-12:55 hrs) / LA 2298 (13:40-14:50 hrs)
J39: PSV total: | K39: =TEXT(TIMEVALUE(I38)-TIMEVALUE(H37)+(I38<H37),"[h]:mm") -> 3:15
B41: Pairing ID | C41: FECHA REAL | D41: Day of Week | E41: Flight No | F41: Dep Stn | G41: Arr Stn | H41: STD | I41: STA | J41: subflota | K41: Conexion | L41: HBT
B42: 133 | C42: 01/10/2026 | D42: jueves | E42: 2028 | F42: LIM | G42: CUZ | H42: 13:25:00 | I42: 14:45:00 | J42: 320 | L42: 01:20:00 | Q42: =B42 -> 133 | R42: =C42 -> 01/10/2026 | S42: =D42 -> jueves | T42: =E42&"/"&E43 -> 2028/2029 | U42: =F42&"-"&G42&"-"&F42 -> LIM-CUZ-LIM | V42: =IF($M$42="","",$M$42) | W42: =IF($O$42="","",$O$42) | X42: =J42 -> 320
B43: 133 | C43: 01/10/2026 | D43: jueves | E43: 2029 | F43: CUZ | G43: LIM | H43: 15:30:00 | I43: 17:05:00 | J43: 320 | K43: =TEXT(TIMEVALUE(H43)-TIMEVALUE(I42)+(TIMEVALUE(H43)<TIMEVALUE(I42)),"[h]:mm") -> 0:45 | L43: 01:35:00 | O43: ="LIM-"&G42&"-LIM LA "&E42&" ("&LEFT(H42,5)&"-"&LEFT(I42,5)&" hrs) / LA "&E43&" ("&LEFT(H43,5)&"-"&LEFT(I43,5)&" hrs)" -> LIM-CUZ-LIM LA 2028 (13:25-14:45 hrs) / LA 2029 (15:30-17:05 hrs)
B44: 153 | C44: 01/10/2026 | D44: jueves | E44: 2223 | F44: LIM | G44: CUZ | H44: 18:20:00 | I44: 19:40:00 | J44: 320 | K44: =TEXT(TIMEVALUE(H44)-TIMEVALUE(I43)+(TIMEVALUE(H44)<TIMEVALUE(I43)),"[h]:mm") -> 1:15 | L44: 01:20:00 | M44: =IF($M$42="","",$M$42) | O44: =IF($O$42="","",$O$42) | Q44: =B44 -> 153 | R44: =C44 -> 01/10/2026 | S44: =D44 -> jueves | T44: =E44&"/"&E45 -> 2223/2224 | U44: =F44&"-"&G44&"-"&F44 -> LIM-CUZ-LIM | V44: =IF($M$42="","",$M$42) | W44: =IF($O$42="","",$O$42) | X44: =J44 -> 320
B45: 153 | C45: 01/10/2026 | D45: jueves | E45: 2224 | F45: CUZ | G45: LIM | H45: 21:20:00 | I45: 22:55:00 | J45: 320 | K45: =TEXT(TIMEVALUE(H45)-TIMEVALUE(I44)+(TIMEVALUE(H45)<TIMEVALUE(I44)),"[h]:mm") -> 1:40 | L45: 01:35:00 | O45: ="LIM-"&G44&"-LIM LA "&E44&" ("&LEFT(H44,5)&"-"&LEFT(I44,5)&" hrs) / LA "&E45&" ("&LEFT(H45,5)&"-"&LEFT(I45,5)&" hrs)" -> LIM-CUZ-LIM LA 2223 (18:20-19:40 hrs) / LA 2224 (21:20-22:55 hrs)
J46: PSV total: | K46: =TEXT(TIMEVALUE(I45)-TIMEVALUE(H42)+(I45<H42),"[h]:mm") -> 9:30
B48: Pairing ID | C48: FECHA REAL | D48: Day of Week | E48: Flight No | F48: Dep Stn | G48: Arr Stn | H48: STD | I48: STA | J48: subflota | K48: Conexion | L48: HBT
B49: 136 | C49: 01/10/2026 | D49: jueves | E49: 2152 | F49: LIM | G49: CIX | H49: 13:50:00 | I49: 15:20:00 | J49: 320 | L49: 01:30:00 | Q49: =B49 -> 136 | R49: =C49 -> 01/10/2026 | S49: =D49 -> jueves | T49: =E49&"/"&E50 -> 2152/2153 | U49: =F49&"-"&G49&"-"&F49 -> LIM-CIX-LIM | V49: =IF($M$49="","",$M$49) | W49: =IF($O$49="","",$O$49) | X49: =J49 -> 320
...

Sheet Instructores
A1: Instructor | B1: BP | C1: Nombre
A2: Christian Rondon | B2: 1271571 | C2: RONDON BARRUTIA CHRISTIAN ERIC
A3: Erika Davila | B3: 967092 | C3: DAVILA BELLO MARIA ERIKA
A4: Sebastian Correa | B4: 2396710 | C4: CORREA GARCIA JUAN SEBASTIAN
A5: Fiorella Ruiz | B5: 2713993 | C5: RUIZ RIOJA FIORELLA DEL PILAR
A6: Jazmin Guerra | B6: 29530 | C6: GUERRA SUAREZ JAZMIN
A7: Jennifert Acurio | B7: 3779550 | C7: ACURIO DARGENT JENNIFERT MILAGROS
A8: Karen Santa Cruz | B8: 2843319 | C8: SANTA CRUZ HUAMAN KAREN
A9: Luis Bacigalupo | B9: 2963161 | C9: BACIGALUPO FLORES LUIS ENRIQUE
A10: Claudia Flores | B10: 3217561 | C10: FLORES FUENTES DAVILA CLAUDIA ALEXANDRA
A11: Karla Moz | B11: 71348 | C11: MOZ MONTES KARLA LISSETTE
A12: Elizabeth Torres | B12: 2369641 | C12: TORRES POLO ELIZABETH DEL PILAR
... A23: Gianfranco Celiz | B23: 3841387 | C23: CELIZ ROSSI GIANFRANCO PAOLO

Sheet Resumen Final
A1: TRIP | B1: Fecha | C1: DíaSEM | D1: Vuelo | E1: Ruta | F1: BP INS | G1: INS | H1: ACTIVIDAD | I1: FLOTA | J1: Nombre INS | K1: CUPOS
A2: ='Pairings NB'!B9 -> 113 | B2: ='Pairings NB'!C9 -> 01/10/2026 | C2: ='Pairings NB'!D9 -> jueves | D2: ='Pairings NB'!E9&"/"&'Pairings NB'!E10 -> 2007/2008 | E2: ='Pairings NB'!F9&"-"&'Pairings NB'!G9&"-"&'Pairings NB'!F9 -> LIM-CUZ-LIM | F2: =IFERROR(VLOOKUP('Pairings NB'!$M$9,Instructores!$A:$C,2,FALSE),"") | G2: ='Pairings NB'!$M$9 -> 0 | H2: ='Pairings NB'!$O$9 -> 0 | I2: ='Pairings NB'!J9 -> 320 | J2: =IFERROR(VLOOKUP('Pairings NB'!$M$9,Instructores!$A:$C,3,FALSE),"") | K2: =IF('Pairings NB'!J9=320,4,3) -> 4
A3: ='Pairings NB'!B11 -> 135 | B3: ='Pairings NB'!C11 -> 01/10/2026 | C3: ='Pairings NB'!D11 -> jueves | D3: ='Pairings NB'!E11&"/"&'Pairings NB'!E12 -> 2152/2153 | E3: ='Pairings NB'!F11&"-"&'Pairings NB'!G11&"-"&'Pairings NB'!F11 -> LIM-CIX-LIM | F3: =IFERROR(VLOOKUP('Pairings NB'!$M$9,Instructores!$A:$C,2,FALSE),"") | G3: ='Pairings NB'!$M$9 -> 0 | H3: ='Pairings NB'!$O$9 -> 0 | I3: ='Pairings NB'!J11 -> 320 | J3: =IFERROR(VLOOKUP('Pairings NB'!$M$9,Instructores!$A:$C,3,FALSE),"") | K3: =IF('Pairings NB'!J11=320,4,3) -> 4
A4: ='Pairings NB'!B16 -> 117 | B4: ='Pairings NB'!C16 -> 01/10/2026 | C4: ='Pairings NB'!D16 -> jueves | D4: ='Pairings NB'!E16&"/"&'Pairings NB'!E17 -> 2260/2261 | E4: ='Pairings NB'!F16&"-"&'Pairings NB'!G16&"-"&'Pairings NB'!F16 -> LIM-PEM-LIM | F4: =IFERROR(VLOOKUP('Pairings NB'!$M$16,Instructores!$A:$C,2,FALSE),"") | G4: ='Pairings NB'!$M$16 -> 0 | H4: ='Pairings NB'!$O$16 -> 0 | I4: ='Pairings NB'!J16 -> 320 | J4: =IFERROR(VLOOKUP('Pairings NB'!$M$16,Instructores!$A:$C,3,FALSE),"") | K4: =IF('Pairings NB'!J16=320,4,3) -> 4
A5: ='Pairings NB'!B18 -> 144 | B5: ='Pairings NB'!C18 -> 01/10/2026 | C5: ='Pairings NB'!D18 -> jueves | D5: ='Pairings NB'!E18&"/"&'Pairings NB'!E19 -> 2297/2296 | E5: ='Pairings NB'!F18&"-"&'Pairings NB'!G18&"-"&'Pairings NB'!F18 -> LIM-CJA-LIM | F5: =IFERROR(VLOOKUP('Pairings NB'!$M$16,Instructores!$A:$C,2,FALSE),"") | G5: ='Pairings NB'!$M$16 -> 0 | H5: ='Pairings NB'!$O$16 -> 0 | I5: ='Pairings NB'!J18 -> 320 | J5: =IFERROR(VLOOKUP('Pairings NB'!$M$16,Instructores!$A:$C,3,FALSE),"") | K5: =IF('Pairings NB'!J18=320,4,3) -> 4
A6: ='Pairings NB'!B23 -> 118 | B6: ='Pairings NB'!C23 -> 01/10/2026 | C6: ='Pairings NB'!D23 -> jueves | D6: ='Pairings NB'!E23&"/"&'Pairings NB'!E24 -> 2109/2108 | E6: ='Pairings NB'!F23&"-"&'Pairings NB'!G23&"-"&'Pairings NB'!F23 -> LIM-AQP-LIM | F6: =IFERROR(VLOOKUP('Pairings NB'!$M$23,Instructores!$A:$C,2,FALSE),"") | G6: ='Pairings NB'!$M$23 -> 0 | H6: ='Pairings NB'!$O$23 -> 0 | I6: ='Pairings NB'!J23 -> 320 | J6: =IFERROR(VLOOKUP('Pairings NB'!$M$23,Instructores!$A:$C,3,FALSE),"") | K6: =IF('Pairings NB'!J23=320,4,3) -> 4
A7: ='Pairings NB'!B25 -> 145 | B7: ='Pairings NB'!C25 -> 01/10/2026 | C7: ='Pairings NB'!D25 -> jueves | D7: ='Pairings NB'!E25&"/"&'Pairings NB'!E26 -> 2360/2361 | E7: ='Pairings NB'!F25&"-"&'Pairings NB'!G25&"-"&'Pairings NB'!F25 -> LIM-PCL-LIM | F7: =IFERROR(VLOOKUP('Pairings NB'!$M$23,Instructores!$A:$C,2,FALSE),"") | G7: ='Pairings NB'!$M$23 -> 0 | H7: ='Pairings NB'!$O$23 -> 0 | I7: ='Pairings NB'!J25 -> 319 | J7: =IFERROR(VLOOKUP('Pairings NB'!$M$23,Instructores!$A:$C,3,FALSE),"") | K7: =IF('Pairings NB'!J25=320,4,3) -> 3
A8: ='Pairings NB'!B30 -> 119 | B8: ='Pairings NB'!C30 -> 01/10/2026 | C8: ='Pairings NB'!D30 -> jueves | D8: ='Pairings NB'!E30&"/"&'Pairings NB'!E31 -> 2019/2038 | E8: ='Pairings NB'!F30&"-"&'Pairings NB'!G30&"-"&'Pairings NB'!F30 -> LIM-IQT-LIM | F8: =IFERROR(VLOOKUP('Pairings NB'!$M$30,Instructores!$A:$C,2,FALSE),"") | G8: ='Pairings NB'!$M$30 -> 0 | H8: ='Pairings NB'!$O$30 -> 0 | I8: ='Pairings NB'!J30 -> 319 | J8: =IFERROR(VLOOKUP('Pairings NB'!$M$30,Instructores!$A:$C,3,FALSE),"") | K8: =IF('Pairings NB'!J30=320,4,3) -> 3
A9: ='Pairings NB'!B32 -> 151 | B9: ='Pairings NB'!C32 -> 01/10/2026 | C9: ='Pairings NB'!D32 -> jueves | D9: ='Pairings NB'!E32&"/"&'Pairings NB'!E33 -> 2115/2114 | E9: ='Pairings NB'!F32&"-"&'Pairings NB'!G32&"-"&'Pairings NB'!F32 -> LIM-AQP-LIM | F9: =IFERROR(VLOOKUP('Pairings NB'!$M$30,Instructores!$A:$C,2,FALSE),"") | G9: ='Pairings NB'!$M$30 -> 0 | H9: ='Pairings NB'!$O$30 -> 0 | I9: ='Pairings NB'!J32 -> 320 | J9: =IFERROR(VLOOKUP('Pairings NB'!$M$30,Instructores!$A:$C,3,FALSE),"") | K9: =IF('Pairings NB'!J32=320,4,3) -> 4
A10: ='Pairings NB'!B37 -> 120 | B10: ='Pairings NB'!C37 -> 01/10/2026 | C10: ='Pairings NB'!D37 -> jueves | D10: ='Pairings NB'!E37&"/"&'Pairings NB'!E38 -> 2299/2298 | E10: ='Pairings NB'!F37&"-"&'Pairings NB'!G37&"-"&'Pairings NB'!F37 -> LIM-CJA-LIM | F10: =IFERROR(VLOOKUP('Pairings NB'!$M$37,Instructores!$A:$C,2,FALSE),"") | G10: ='Pairings NB'!$M$37 -> 0 | H10: ='Pairings NB'!$O$37 -> 0 | I10: ='Pairings NB'!J37 -> 320 | J10: =IFERROR(VLOOKUP('Pairings NB'!$M$37,Instructores!$A:$C,3,FALSE),"") | K10: =IF('Pairings NB'!J37=320,4,3) -> 4
A11: ='Pairings NB'!B42 -> 133 | B11: ='Pairings NB'!C42 -> 01/10/2026 | C11: ='Pairings NB'!D42 -> jueves | D11: ='Pairings NB'!E42&"/"&'Pairings NB'!E43 -> 2028/2029 | E11: ='Pairings NB'!F42&"-"&'Pairings NB'!G42&"-"&'Pairings NB'!F42 -> LIM-CUZ-LIM | F11: =IFERROR(VLOOKUP('Pairings NB'!$M$42,Instructores!$A:$C,2,FALSE),"") | G11: ='Pairings NB'!$M$42 -> 0 | H11: ='Pairings NB'!$O$42 -> 0 | I11: ='Pairings NB'!J42 -> 320 | J11: =IFERROR(VLOOKUP('Pairings NB'!$M$42,Instructores!$A:$C,3,FALSE),"") | K11: =IF('Pairings NB'!J42=320,4,3) -> 4
A12: ='Pairings NB'!B44 -> 153 | B12: ='Pairings NB'!C44 -> 01/10/2026 | C12: ='Pairings NB'!D44 -> jueves | D12: ='Pairings NB'!E44&"/"&'Pairings NB'!E45 -> 2223/2224 | E12: ='Pairings NB'!F44&"-"&'Pairings NB'!G44&"-"&'Pairings NB'!F44 -> LIM-CUZ-LIM | F12: =IFERROR(VLOOKUP('Pairings NB'!$M$42,Instructores!$A:$C,2,FALSE),"") | G12: ='Pairings NB'!$M$42 -> 0 | H12: ='Pairings NB'!$O$42 -> 0 | I12: ='Pairings NB'!J44 -> 320 | J12: =IFERROR(VLOOKUP('Pairings NB'!$M$42,Instructores!$A:$C,3,FALSE),"") | K12: =IF('Pairings NB'!J44=320,4,3) -> 4
A13: ='Pairings NB'!B49 -> 136 | B13: ='Pairings NB'!C49 -> 01/10/2026 | C13: ='Pairings NB'!D49 -> jueves | D13: ='Pairings NB'!E49&"/"&'Pairings NB'!E50 -> 2152/2153 | E13: ='Pairings NB'!F49&"-"&'Pairings NB'!G49&"-"&'Pairings NB'!F49 -> LIM-CIX-LIM | F13: =IFERROR(VLOOKUP('Pairings NB'!$M$49,Instructores!$A:$C,2,FALSE),"") | G13: ='Pairings NB'!$M$49 -> 0 | H13: ='Pairings NB'!$O$49 -> 0 | I13: ='Pairings NB'!J49 -> 320 | J13: =IFERROR(VLOOKUP('Pairings NB'!$M$49,Instructores!$A:$C,3,FALSE),"") | K13: =IF('Pairings NB'!J49=320,4,3) -> 4
A14: ='Pairings NB'!B54 -> 137 | B14: ='Pairings NB'!C54 -> 01/10/2026 | C14: ='Pairings NB'!D54 -> jueves | D14: ='Pairings NB'!E54&"/"&'Pairings NB'!E55 -> 2055/2056 | E14: ='Pairings NB'!F54&"-"&'Pairings NB'!G54&"-"&'Pairings NB'!F54 -> LIM-AQP-LIM | F14: =IFERROR(VLOOKUP('Pairings NB'!$M$54,Instructores!$A:$C,2,FALSE),"") | G14: ='Pairings NB'!$M$54 -> 0 | H14: ='Pairings NB'!$O$54 -> 0 | I14: ='Pairings NB'!J54 -> 320 | J14: =IFERROR(VLOOKUP('Pairings NB'!$M$54,Instructores!$A:$C,3,FALSE),"") | K14: =IF('Pairings NB'!J54=320,4,3) -> 4
A15: ='Pairings NB'!B59 -> 139 | B15: ='Pairings NB'!C59 -> 01/10/2026 | C15: ='Pairings NB'!D59 -> jueves | D15: ='Pairings NB'!E59&"/"&'Pairings NB'!E60 -> 2154/2155 | E15: ='Pairings NB'!F59&"-"&'Pairings NB'!G59&"-"&'Pairings NB'!F59 -> LIM-CUZ-LIM | F15: =IFERROR(VLOOKUP('Pairings NB'!$M$59,Instructores!$A:$C,2,FALSE),"") | G15: ='Pairings NB'!$M$59 -> 0 | H15: ='Pairings NB'!$O$59 -> 0 | I15: ='Pairings NB'!J59 -> 320 | J15: =IFERROR(VLOOKUP('Pairings NB'!$M$59,Instructores!$A:$C,3,FALSE),"") | K15: =IF('Pairings NB'!J59=320,4,3) -> 4
A16: ='Pairings NB'!B64 -> 140 | B16: ='Pairings NB'!C64 -> 01/10/2026 | C16: ='Pairings NB'!D64 -> jueves | D16: ='Pairings NB'!E64&"/"&'Pairings NB'!E65 -> 2264/2265 | E16: ='Pairings NB'!F64&"-"&'Pairings NB'!G64&"-"&'Pairings NB'!F64 -> LIM-PEM-LIM | F16: =IFERROR(VLOOKUP('Pairings NB'!$M$64,Instructores!$A:$C,2,FALSE),"") | G16: ='Pairings NB'!$M$64 -> 0 | H16: ='Pairings NB'!$O$64 -> 0 | I16: ='Pairings NB'!J64 -> 320 | J16: =IFERROR(VLOOKUP('Pairings NB'!$M$64,Instructores!$A:$C,3,FALSE),"") | K16: =IF('Pairings NB'!J64=320,4,3) -> 4
A17: ='Pairings NB'!B69 -> 141 | B17: ='Pairings NB'!C69 -> 01/10/2026 | C17: ='Pairings NB'!D69 -> jueves | D17: ='Pairings NB'!E69&"/"&'Pairings NB'!E70 -> 2264/2265 | E17: ='Pairings NB'!F69&"-"&'Pairings NB'!G69&"-"&'Pairings NB'!F69 -> LIM-PEM-LIM | F17: =IFERROR(VLOOKUP('Pairings NB'!$M$69,Instructores!$A:$C,2,FALSE),"") | G17: ='Pairings NB'!$M$69 -> 0 | H17: ='Pairings NB'!$O$69 -> 0 | I17: ='Pairings NB'!J69 -> 320 | J17: =IFERROR(VLOOKUP('Pairings NB'!$M$69,Instructores!$A:$C,3,FALSE),"") | K17: =IF('Pairings NB'!J69=320,4,3) -> 4
A18: ='Pairings NB'!B74 -> 146 | B18: ='Pairings NB'!C74 -> 01/10/2026 | C18: ='Pairings NB'!D74 -> jueves | D18: ='Pairings NB'!E74&"/"&'Pairings NB'!E75 -> 2312/2313 | E18: ='Pairings NB'!F74&"-"&'Pairings NB'!G74&"-"&'Pairings NB'!F74 -> LIM-CIX-LIM | F18: =IFERROR(VLOOKUP('Pairings NB'!$M$74,Instructores!$A:$C,2,FALSE),"") | G18: ='Pairings NB'!$M$74 -> 0 | H18: ='Pairings NB'!$O$74 -> 0 | I18: ='Pairings NB'!J74 -> 320 | J18: =IFERROR(VLOOKUP('Pairings NB'!$M$74,Instructores!$A:$C,3,FALSE),"") | K18: =IF('Pairings NB'!J74=320,4,3) -> 4
A19: ='Pairings NB'!B79 -> 147 | B19: ='Pairings NB'!C79 -> 01/10/2026 | C19: ='Pairings NB'!D79 -> jueves | D19: ='Pairings NB'!E79&"/"&'Pairings NB'!E80 -> 2312/2313 | E19: ='Pairings NB'!F79&"-"&'Pairings NB'!G79&"-"&'Pairings NB'!F79 -> LIM-CIX-LIM | F19: =IFERROR(VLOOKUP('Pairings NB'!$M$79,Instructores!$A:$C,2,FALSE),"") | G19: ='Pairings NB'!$M$79 -> 0 | H19: ='Pairings NB'!$O$79 -> 0 | I19: ='Pairings NB'!J79 -> 320 | J19: =IFERROR(VLOOKUP('Pairings NB'!$M$79,Instructores!$A:$C,3,FALSE),"") | K19: =IF('Pairings NB'!J79=320,4,3) -> 4
A20: ='Pairings NB'!B84 -> 148 | B20: ='Pairings NB'!C84 -> 01/10/2026 | C20: ='Pairings NB'!D84 -> jueves | D20: ='Pairings NB'!E84&"/"&'Pairings NB'!E85 -> 2301/2300 | E20: ='Pairings NB'!F84&"-"&'Pairings NB'!G84&"-"&'Pairings NB'!F84 -> LIM-TPP-LIM | F20: =IFERROR(VLOOKUP('Pairings NB'!$M$84,Instructores!$A:$C,2,FALSE),"") | G20: ='Pairings NB'!$M$84 -> 0 | H20: ='Pairings NB'!$O$84 -> 0 | I20: ='Pairings NB'!J84 -> 320 | J20: =IFERROR(VLOOKUP('Pairings NB'!$M$84,Instructores!$A:$C,3,FALSE),"") | K20: =IF('Pairings NB'!J84=320,4,3) -> 4
A21: ='Pairings NB'!B89 -> 195 | B21: ='Pairings NB'!C89 -> 02/10/2026 | C21: ='Pairings NB'!D89 -> viernes | D21: ='Pairings NB'!E89&"/"&'Pairings NB'!E90 -> 2007/2008 | E21: ='Pairings NB'!F89&"-"&'Pairings NB'!G89&"-"&'Pairings NB'!F89 -> LIM-CUZ-LIM | F21: =IFERROR(VLOOKUP('Pairings NB'!$M$89,Instructores!$A:$C,2,FALSE),"") | G21: ='Pairings NB'!$M$89 -> 0 | H21: ='Pairings NB'!$O$89 -> 0 | I21: ='Pairings NB'!J89 -> 320 | J21: =IFERROR(VLOOKUP('Pairings NB'!$M$89,Instructores!$A:$C,3,FALSE),"") | K21: =IF('Pairings NB'!J89=320,4,3) -> 4
A22: ='Pairings NB'!B91 -> 216 | B22: ='Pairings NB'!C91 -> 02/10/2026 | C22: ='Pairings NB'!D91 -> viernes | D22: ='Pairings NB'!E91&"/"&'Pairings NB'!E92 -> 2152/2153 | E22: ='Pairings NB'!F91&"-"&'Pairings NB'!G91&"-"&'Pairings NB'!F91 -> LIM-CIX-LIM | F22: =IFERROR(VLOOKUP('Pairings NB'!$M$89,Instructores!$A:$C,2,FALSE),"") | G22: ='Pairings NB'!$M$89 -> 0 | H22: ='Pairings NB'!$O$89 -> 0 | I22: ='Pairings NB'!J91 -> 320 | J22: =IFERROR(VLOOKUP('Pairings NB'!$M$89,Instructores!$A:$C,3,FALSE),"") | K22: =IF('Pairings NB'!J91=320,4,3) -> 4
A23: ='Pairings NB'!B96 -> 199 | B23: ='Pairings NB'!C96 -> 02/10/2026 | C23: ='Pairings NB'!D96 -> viernes | D23: ='Pairings NB'!E96&"/"&'Pairings NB'!E97 -> 2075/2076 | E23: ='Pairings NB'!F96&"-"&'Pairings NB'!G96&"-"&'Pairings NB'!F96 -> LIM-CUZ-LIM | F23: =IFERROR(VLOOKUP('Pairings NB'!$M$96,Instructores!$A:$C,2,FALSE),"") | G23: ='Pairings NB'!$M$96 -> 0 | H23: ='Pairings NB'!$O$96 -> 0 | I23: ='Pairings NB'!J96 -> 320 | J23: =IFERROR(VLOOKUP('Pairings NB'!$M$96,Instructores!$A:$C,3,FALSE),"") | K23: =IF('Pairings NB'!J96=320,4,3) -> 4
A24: ='Pairings NB'!B98 -> 223 | B24: ='Pairings NB'!C98 -> 02/10/2026 | C24: ='Pairings NB'!D98 -> viernes | D24: ='Pairings NB'!E98&"/"&'Pairings NB'!E99 -> 2297/2296 | E24: ='Pairings NB'!F98&"-"&'Pairings NB'!G98&"-"&'Pairings NB'!F98 -> LIM-CJA-LIM | F24: =IFERROR(VLOOKUP('Pairings NB'!$M$96,Instructores!$A:$C,2,FALSE),"") | G24: ='Pairings NB'!$M$96 -> 0 | H24: ='Pairings NB'!$O$96 -> 0 | I24: ='Pairings NB'!J98 -> 320 | J24: =IFERROR(VLOOKUP('Pairings NB'!$M$96,Instructores!$A:$C,3,FALSE),"") | K24: =IF('Pairings NB'!J98=320,4,3) -> 4
A25: ='Pairings NB'!B103 -> 200 | B25: ='Pairings NB'!C103 -> 02/10/2026 | C25: ='Pairings NB'!D103 -> viernes | D25: ='Pairings NB'!E103&"/"&'Pairings NB'!E104 -> 2019/2038 | E25: ='Pairings NB'!F103&"-"&'Pairings NB'!G103&"-"&'Pairings NB'!F103 -> LIM-IQT-LIM | F25: =IFERROR(VLOOKUP('Pairings NB'!$M$103,Instructores!$A:$C,2,FALSE),"") | G25: ='Pairings NB'!$M$103 -> 0 | H25: ='Pairings NB'!$O$103 -> 0 | I25: ='Pairings NB'!J103 -> 319 | J25: =IFERROR(VLOOKUP('Pairings NB'!$M$103,Instructores!$A:$C,3,FALSE),"") | K25: =IF('Pairings NB'!J103=320,4,3) -> 3
A26: ='Pairings NB'!B108 -> 201 | B26: ='Pairings NB'!C108 -> 02/10/2026 | C26: ='Pairings NB'!D108 -> viernes | D26: ='Pairings NB'!E108&"/"&'Pairings NB'!E109 -> 2299/2298 | E26: ='Pairings NB'!F108&"-"&'Pairings NB'!G108&"-"&'Pairings NB'!F108 -> LIM-CJA-LIM | F26: =IFERROR(VLOOKUP('Pairings NB'!$M$108,Instructores!$A:$C,2,FALSE),"") | G26: ='Pairings NB'!$M$108 -> 0 | H26: ='Pairings NB'!$O$108 -> 0 | I26: ='Pairings NB'!J108 -> 320 | J26: =IFERROR(VLOOKUP('Pairings NB'!$M$108,Instructores!$A:$C,3,FALSE),"") | K26: =IF('Pairings NB'!J108=320,4,3) -> 4
A27: ='Pairings NB'!B110 -> 231 | B27: ='Pairings NB'!C110 -> 02/10/2026 | C27: ='Pairings NB'!D110 -> viernes | D27: ='Pairings NB'!E110&"/"&'Pairings NB'!E111 -> 2127/2026 | E27: ='Pairings NB'!F110&"-"&'Pairings NB'!G110&"-"&'Pairings NB'!F110 -> LIM-CUZ-LIM | F27: =IFERROR(VLOOKUP('Pairings NB'!$M$108,Instructores!$A:$C,2,FALSE),"") | G27: ='Pairings NB'!$M$108 -> 0 | H27: ='Pairings NB'!$O$108 -> 0 | I27: ='Pairings NB'!J110 -> 320 | J27: =IFERROR(VLOOKUP('Pairings NB'!$M$108,Instructores!$A:$C,3,FALSE),"") | K27: =IF('Pairings NB'!J110=320,4,3) -> 4
A28: ='Pairings NB'!B115 -> 203 | B28: ='Pairings NB'!C115 -> 02/10/2026 | C28: ='Pairings NB'!D115 -> viernes | D28: ='Pairings NB'!E115&"/"&'Pairings NB'!E116 -> 2111/2110 | E28: ='Pairings NB'!F115&"-"&'Pairings NB'!G115&"-"&'Pairings NB'!F115 -> LIM-AQP-LIM | F28: =IFERROR(VLOOKUP('Pairings NB'!$M$115,Instructores!$A:$C,2,FALSE),"") | G28: ='Pairings NB'!$M$115 -> 0 | H28: ='Pairings NB'!$O$115 -> 0 | I28: ='Pairings NB'!J115 -> 319 | J28: =IFERROR(VLOOKUP('Pairings NB'!$M$115,Instructores!$A:$C,3,FALSE),"") | K28: =IF('Pairings NB'!J115=320,4,3) -> 3
A29: ='Pairings NB'!B120 -> 205 | B29: ='Pairings NB'!C120 -> 02/10/2026 | C29: ='Pairings NB'!D120 -> viernes | D29: ='Pairings NB'!E120&"/"&'Pairings NB'!E121 -> 2356/2357 | E29: ='Pairings NB'!F120&"-"&'Pairings NB'!G120&"-"&'Pairings NB'!F120 -> LIM-CUZ-LIM | F29: =IFERROR(VLOOKUP('Pairings NB'!$M$120,Instructores!$A:$C,2,FALSE),"") | G29: ='Pairings NB'!$M$120 -> 0 | H29: ='Pairings NB'!$O$120 -> 0 | I29: ='Pairings NB'!J120 -> 319 | J29: =IFERROR(VLOOKUP('Pairings NB'!$M$120,Instructores!$A:$C,3,FALSE),"") | K29: =IF('Pairings NB'!J120=320,4,3) -> 3
A30: ='Pairings NB'!B125 -> 210 | B30: ='Pairings NB'!C125 -> 02/10/2026 | C30: ='Pairings NB'!D125 -> viernes | D30: ='Pairings NB'!E125&"/"&'Pairings NB'!E126 -> 2043/2044 | E30: ='Pairings NB'!F125&"-"&'Pairings NB'!G125&"-"&'Pairings NB'!F125 -> LIM-AQP-LIM | F30: =IFERROR(VLOOKUP('Pairings NB'!$M$125,Instructores!$A:$C,2,FALSE),"") | G30: ='Pairings NB'!$M$125 -> 0 | H30: ='Pairings NB'!$O$125 -> 0 | I30: ='Pairings NB'!J125 -> 320 | J30: =IFERROR(VLOOKUP('Pairings NB'!$M$125,Instructores!$A:$C,3,FALSE),"") | K30: =IF('Pairings NB'!J125=320,4,3) -> 4
A31: ='Pairings NB'!B130 -> 217 | B31: ='Pairings NB'!C130 -> 02/10/2026 | C31: ='Pairings NB'!D130 -> viernes | D31: ='Pairings NB'!E130&"/"&'Pairings NB'!E131 -> 2087/2088 | E31: ='Pairings NB'!F130&"-"&'Pairings NB'!G130&"-"&'Pairings NB'!F130 -> LIM-TPP-LIM | F31: =IFERROR(VLOOKUP('Pairings NB'!$M$130,Instructores!$A:$C,2,FALSE),"") | G31: ='Pairings NB'!$M$130 -> 0 | H31: ='Pairings NB'!$O$130 -> 0 | I31: ='Pairings NB'!J130 -> 320 | J31: =IFERROR(VLOOKUP('Pairings NB'!$M$130,Instructores!$A:$C,3,FALSE),"") | K31: =IF('Pairings NB'!J130=320,4,3) -> 4
A32: ='Pairings NB'!B135 -> 218 | B32: ='Pairings NB'!C135 -> 02/10/2026 | C32: ='Pairings NB'!D135 -> viernes | D32: ='Pairings NB'!E135&"/"&'Pairings NB'!E136 -> 2295/2294 | E32: ='Pairings NB'!F135&"-"&'Pairings NB'!G135&"-"&'Pairings NB'!F135 -> LIM-CJA-LIM | F32: =IFERROR(VLOOKUP('Pairings NB'!$M$135,Instructores!$A:$C,2,FALSE),"") | G32: ='Pairings NB'!$M$135 -> 0 | H32: ='Pairings NB'!$O$135 -> 0 | I32: ='Pairings NB'!J135 -> 320 | J32: =IFERROR(VLOOKUP('Pairings NB'!$M$135,Instructores!$A:$C,3,FALSE),"") | K32: =IF('Pairings NB'!J135=320,4,3) -> 4
A33: ='Pairings NB'!B137 -> 234 | B33: ='Pairings NB'!C137 -> 02/10/2026 | C33: ='Pairings NB'!D137 -> viernes | D33: ='Pairings NB'!E137&"/"&'Pairings NB'!E138 -> 2310/2311 | E33: ='Pairings NB'!F137&"-"&'Pairings NB'!G137&"-"&'Pairings NB'!F137 -> LIM-CIX-LIM | F33: =IFERROR(VLOOKUP('Pairings NB'!$M$135,Instructores!$A:$C,2,FALSE),"") | G33: ='Pairings NB'!$M$135 -> 0 | H33: ='Pairings NB'!$O$135 -> 0 | I33: ='Pairings NB'!J137 -> 320 | J33: =IFERROR(VLOOKUP('Pairings NB'!$M$135,Instructores!$A:$C,3,FALSE),"") | K33: =IF('Pairings NB'!J137=320,4,3) -> 4
A34: ='Pairings NB'!B142 -> 220 | B34: ='Pairings NB'!C142 -> 02/10/2026 | C34: ='Pairings NB'!D142 -> viernes | D34: ='Pairings NB'!E142&"/"&'Pairings NB'!E143 -> 2154/2155 | E34: ='Pairings NB'!F142&"-"&'Pairings NB'!G142&"-"&'Pairings NB'!F142 -> LIM-CUZ-LIM | F34: =IFERROR(VLOOKUP('Pairings NB'!$M$142,Instructores!$A:$C,2,FALSE),"") | G34: ='Pairings NB'!$M$142 -> 0 | H34: ='Pairings NB'!$O$142 -> 0 | I34: ='Pairings NB'!J142 -> 320 | J34: =IFERROR(VLOOKUP('Pairings NB'!$M$142,Instructores!$A:$C,3,FALSE),"") | K34: =IF('Pairings NB'!J142=320,4,3) -> 4
A35: ='Pairings NB'!B147 -> 221 | B35: ='Pairings NB'!C147 -> 02/10/2026 | C35: ='Pairings NB'!D147 -> viernes | D35: ='Pairings NB'!E147&"/"&'Pairings NB'!E148 -> 2154/2155 | E35: ='Pairings NB'!F147&"-"&'Pairings NB'!G147&"-"&'Pairings NB'!F147 -> LIM-CUZ-LIM | F35: =IFERROR(VLOOKUP('Pairings NB'!$M$147,Instructores!$A:$C,2,FALSE),"") | G35: ='Pairings NB'!$M$147 -> 0 | H35: ='Pairings NB'!$O$147 -> 0 | I35: ='Pairings NB'!J147 -> 320 | J35: =IFERROR(VLOOKUP('Pairings NB'!$M$147,Instructores!$A:$C,3,FALSE),"") | K35: =IF('Pairings NB'!J147=320,4,3) -> 4
A36: ='Pairings NB'!B152 -> 224 | B36: ='Pairings NB'!C152 -> 02/10/2026 | C36: ='Pairings NB'!D152 -> viernes | D36: ='Pairings NB'!E152&"/"&'Pairings NB'!E153 -> 2360/2361 | E36: ='Pairings NB'!F152&"-"&'Pairings NB'!G152&"-"&'Pairings NB'!F152 -> LIM-PCL-LIM | F36: =IFERROR(VLOOKUP('Pairings NB'!$M$152,Instructores!$A:$C,2,FALSE),"") | G36: ='Pairings NB'!$M$152 -> 0 | H36: ='Pairings NB'!$O$152 -> 0 | I36: ='Pairings NB'!J152 -> 320 | J36: =IFERROR(VLOOKUP('Pairings NB'!$M$152,Instructores!$A:$C,3,FALSE),"") | K36: =IF('Pairings NB'!J152=320,4,3) -> 4
A37: ='Pairings NB'!B157 -> 225 | B37: ='Pairings NB'!C157 -> 02/10/2026 | C37: ='Pairings NB'!D157 -> viernes | D37: ='Pairings NB'!E157&"/"&'Pairings NB'!E158 -> 2360/2361 | E37: ='Pairings NB'!F157&"-"&'Pairings NB'!G157&"-"&'Pairings NB'!F157 -> LIM-PCL-LIM | F37: =IFERROR(VLOOKUP('Pairings NB'!$M$157,Instructores!$A:$C,2,FALSE),"") | G37: ='Pairings NB'!$M$157 -> 0 | H37: ='Pairings NB'!$O$157 -> 0 | I37: ='Pairings NB'!J157 -> 320 | J37: =IFERROR(VLOOKUP('Pairings NB'!$M$157,Instructores!$A:$C,3,FALSE),"") | K37: =IF('Pairings NB'!J157=320,4,3) -> 4
A38: ='Pairings NB'!B162 -> 226 | B38: ='Pairings NB'!C162 -> 02/10/2026 | C38: ='Pairings NB'!D162 -> viernes | D38: ='Pairings NB'!E162&"/"&'Pairings NB'!E163 -> 2312/2313 | E38: ='Pairings NB'!F162&"-"&'Pairings NB'!G162&"-"&'Pairings NB'!F162 -> LIM-CIX-LIM | F38: =IFERROR(VLOOKUP('Pairings NB'!$M$162,Instructores!$A:$C,2,FALSE),"") | G38: ='Pairings NB'!$M$162 -> 0 | H38: ='Pairings NB'!$O$162 -> 0 | I38: ='Pairings NB'!J162 -> 320 | J38: =IFERROR(VLOOKUP('Pairings NB'!$M$162,Instructores!$A:$C,3,FALSE),"") | K38: =IF('Pairings NB'!J162=320,4,3) -> 4
A39: ='Pairings NB'!B167 -> 227 | B39: ='Pairings NB'!C167 -> 02/10/2026 | C39: ='Pairings NB'!D167 -> viernes | D39: ='Pairings NB'!E167&"/"&'Pairings NB'!E168 -> 2301/2300 | E39: ='Pairings NB'!F167&"-"&'Pairings NB'!G167&"-"&'Pairings NB'!F167 -> LIM-TPP-LIM | F39: =IFERROR(VLOOKUP('Pairings NB'!$M$167,Instructores!$A:$C,2,FALSE),"") | G39: ='Pairings NB'!$M$167 -> 0 | H39: ='Pairings NB'!$O$167 -> 0 | I39: ='Pairings NB'!J167 -> 319 | J39: =IFERROR(VLOOKUP('Pairings NB'!$M$167,Instructores!$A:$C,3,FALSE),"") | K39: =IF('Pairings NB'!J167=320,4,3) -> 3
A40: ='Pairings NB'!B172 -> 236 | B40: ='Pairings NB'!C172 -> 02/10/2026 | C40: ='Pairings NB'!D172 -> viernes | D40: ='Pairings NB'!E172&"/"&'Pairings NB'!E173 -> 2221/2222 | E40: ='Pairings NB'!F172&"-"&'Pairings NB'!G172&"-"&'Pairings NB'!F172 -> LIM-CUZ-LIM | F40: =IFERROR(VLOOKUP('Pairings NB'!$M$172,Instructores!$A:$C,2,FALSE),"") | G40: ='Pairings NB'!$M$172 -> 0 | H40: ='Pairings NB'!$O$172 -> 0 | I40: ='Pairings NB'!J172 -> 320 | J40: =IFERROR(VLOOKUP('Pairings NB'!$M$172,Instructores!$A:$C,3,FALSE),"") | K40: =IF('Pairings NB'!J172=320,4,3) -> 4
...
