Workbook

Sheet Pairings NB
B1: Conexión > o = a 50min y < a 1hr y 30min | D1: NO CONSIDERAR TRU/JUL/JAE/AYP/JAU/IQT | H1: CONSIDERAR PAIRINGS PARTIDOS LCK A320 | K1: Vuelos LCK = Siempre en Flota 320
B2: Vuelos HBT mayor a 1 hora | D2: PSV NO MAYOR A 11 HRS | H2: CONSIDERAR SIEMPRE EL PDR | K2: Vuelos iniciando más de 08:30
D3: NO REPETIR PAIRING EN LCK
Q6: Pairing ID | R6: Fecha | S6: DíaSem | T6: Vuelo | U6: Ruta | V6: Instructor | W6: Actividad | X6: Sub Flota
B8: Pairing ID | C8: FECHA REAL | D8: Day of Week | E8: Flight No | F8: Dep Stn | G8: Arr Stn | H8: STD | I8: STA | J8: subflota | K8: Conexion | L8: HBT
B9: 117 | C9: 01/09/2026 | D9: martes | E9: 2013 | F9: LIM | G9: CUZ | H9: 08:40:00 | I9: 10:00:00 | J9: 320 | L9: 01:20:00 | M9: Christian Rondon | N9: Tripulante Ejemplo 01, Tripulante Ejemplo 02, Tripulante Ejemplo 03, Tripulante Ejemplo 04 | O9: LCK A320F | Q9: =B9 | R9: =C9 | S9: =D9 | T9: =E9&"/"&E10 | U9: =F9&"-"&G9&"-"&F9 | V9: =IF($M$9="","",$M$9) | W9: =IF($O$9="","",$O$9) | X9: =J9
B10: 117 | C10: 01/09/2026 | D10: martes | E10: 2014 | F10: CUZ | G10: LIM | H10: 10:40:00 | I10: 12:15:00 | J10: 320 | K10: =TEXT(TIMEVALUE(H10)-TIMEVALUE(I9)+(TIMEVALUE(H10)<TIMEVALUE(I9)),"[h]:mm") | L10: 01:35:00 | O10: ="LIM-"&G9&"-LIM LA "&E9&" ("&LEFT(H9,5)&"-"&LEFT(I9,5)&" hrs) / LA "&E10&" ("&LEFT(H10,5)&"-"&LEFT(I10,5)&" hrs)"
B11: 139 | C11: 01/09/2026 | D11: martes | E11: 2028 | F11: LIM | G11: CUZ | H11: 13:25:00 | I11: 14:45:00 | J11: 320 | K11: =TEXT(TIMEVALUE(H11)-TIMEVALUE(I10)+(TIMEVALUE(H11)<TIMEVALUE(I10)),"[h]:mm") | L11: 01:20:00 | M11: =IF($M$9="","",$M$9) | O11: =IF($O$9="","",$O$9) | Q11: =B11 | R11: =C11 | S11: =D11 | T11: =E11&"/"&E12 | U11: =F11&"-"&G11&"-"&F11 | V11: =IF($M$9="","",$M$9) | W11: =IF($O$9="","",$O$9) | X11: =J11
B12: 139 | C12: 01/09/2026 | D12: martes | E12: 2029 | F12: CUZ | G12: LIM | H12: 15:30:00 | I12: 17:05:00 | J12: 320 | K12: =TEXT(TIMEVALUE(H12)-TIMEVALUE(I11)+(TIMEVALUE(H12)<TIMEVALUE(I11)),"[h]:mm") | L12: 01:35:00 | O12: ="LIM-"&G11&"-LIM LA "&E11&" ("&LEFT(H11,5)&"-"&LEFT(I11,5)&" hrs) / LA "&E12&" ("&LEFT(H12,5)&"-"&LEFT(I12,5)&" hrs)"
J13: PSV total: | K13: =TEXT(TIMEVALUE(I12)-TIMEVALUE(H9)+(I12<H9),"[h]:mm")
B15: Pairing ID | C15: FECHA REAL | D15: Day of Week | E15: Flight No | F15: Dep Stn | G15: Arr Stn | H15: STD | I15: STA | J15: subflota | K15: Conexion | L15: HBT
B16: 121 | C16: 01/09/2026 | D16: martes | E16: 2123 | F16: LIM | G16: AQP | H16: 09:15:00 | I16: 10:45:00 | J16: 319 | L16: 01:30:00 | M16: Fiorella Ruiz | N16: Tripulante Ejemplo 05, Tripulante Ejemplo 06, Tripulante Ejemplo 07 | O16: Reentrenamiento A320F | Q16: =B16 | R16: =C16 | S16: =D16 | T16: =E16&"/"&E17 | U16: =F16&"-"&G16&"-"&F16 | V16: =IF($M$16="","",$M$16) | W16: =IF($O$16="","",$O$16) | X16: =J16
B17: 121 | C17: 01/09/2026 | D17: martes | E17: 2124 | F17: AQP | G17: LIM | H17: 11:35:00 | I17: 13:10:00 | J17: 319 | K17: =TEXT(TIMEVALUE(H17)-TIMEVALUE(I16)+(TIMEVALUE(H17)<TIMEVALUE(I16)),"[h]:mm") | L17: 01:35:00 | O17: ="LIM-"&G16&"-LIM LA "&E16&" ("&LEFT(H16,5)&"-"&LEFT(I16,5)&" hrs) / LA "&E17&" ("&LEFT(H17,5)&"-"&LEFT(I17,5)&" hrs)"
B18: 142 | C18: 01/09/2026 | D18: martes | E18: 2295 | F18: LIM | G18: CJA | H18: 14:10:00 | I18: 15:30:00 | J18: 320 | K18: =TEXT(TIMEVALUE(H18)-TIMEVALUE(I17)+(TIMEVALUE(H18)<TIMEVALUE(I17)),"[h]:mm") | L18: 01:20:00 | M18: =IF($M$16="","",$M$16) | O18: =IF($O$16="","",$O$16) | Q18: =B18 | R18: =C18 | S18: =D18 | T18: =E18&"/"&E19 | U18: =F18&"-"&G18&"-"&F18 | V18: =IF($M$16="","",$M$16) | W18: =IF($O$16="","",$O$16) | X18: =J18
B19: 142 | C19: 01/09/2026 | D19: martes | E19: 2294 | F19: CJA | G19: LIM | H19: 16:10:00 | I19: 17:15:00 | J19: 320 | K19: =TEXT(TIMEVALUE(H19)-TIMEVALUE(I18)+(TIMEVALUE(H19)<TIMEVALUE(I18)),"[h]:mm") | L19: 01:05:00 | O19: ="LIM-"&G18&"-LIM LA "&E18&" ("&LEFT(H18,5)&"-"&LEFT(I18,5)&" hrs) / LA "&E19&" ("&LEFT(H19,5)&"-"&LEFT(I19,5)&" hrs)"
J20: PSV total: | K20: =TEXT(TIMEVALUE(I19)-TIMEVALUE(H16)+(I19<H16),"[h]:mm")
B22: Pairing ID | C22: FECHA REAL | D22: Day of Week | E22: Flight No | F22: Dep Stn | G22: Arr Stn | H22: STD | I22: STA | J22: subflota | K22: Conexion | L22: HBT
B23: 127 | C23: 01/09/2026 | D23: martes | E23: 2019 | F23: LIM | G23: IQT | H23: 11:35:00 | I23: 13:25:00 | J23: 320 | L23: 01:50:00 | M23: Jefferson Mendez | N23: Tripulante Ejemplo 08, Tripulante Ejemplo 09, Tripulante Ejemplo 10, Tripulante Ejemplo 11 | O23: Reentrenamiento A320F | Q23: =B23 | R23: =C23 | S23: =D23 | T23: =E23&"/"&E24 | U23: =F23&"-"&G23&"-"&F23 | V23: =IF($M$23="","",$M$23) | W23: =IF($O$23="","",$O$23) | X23: =J23
B24: 127 | C24: 01/09/2026 | D24: martes | E24: 2038 | F24: IQT | G24: LIM | H24: 14:05:00 | I24: 15:55:00 | J24: 320 | K24: =TEXT(TIMEVALUE(H24)-TIMEVALUE(I23)+(TIMEVALUE(H24)<TIMEVALUE(I23)),"[h]:mm") | L24: 01:50:00 | O24: ="LIM-"&G23&"-LIM LA "&E23&" ("&LEFT(H23,5)&"-"&LEFT(I23,5)&" hrs) / LA "&E24&" ("&LEFT(H24,5)&"-"&LEFT(I24,5)&" hrs)"
B25: 156 | C25: 01/09/2026 | D25: martes | E25: 2213 | F25: LIM | G25: CIX | H25: 17:20:00 | I25: 18:50:00 | J25: 320 | K25: =TEXT(TIMEVALUE(H25)-TIMEVALUE(I24)+(TIMEVALUE(H25)<TIMEVALUE(I24)),"[h]:mm") | L25: 01:30:00 | M25: =IF($M$23="","",$M$23) | O25: =IF($O$23="","",$O$23) | Q25: =B25 | R25: =C25 | S25: =D25 | T25: =E25&"/"&E26 | U25: =F25&"-"&G25&"-"&F25 | V25: =IF($M$23="","",$M$23) | W25: =IF($O$23="","",$O$23) | X25: =J25
B26: 156 | C26: 01/09/2026 | D26: martes | E26: 2214 | F26: CIX | G26: LIM | H26: 19:25:00 | I26: 20:40:00 | J26: 320 | K26: =TEXT(TIMEVALUE(H26)-TIMEVALUE(I25)+(TIMEVALUE(H26)<TIMEVALUE(I25)),"[h]:mm") | L26: 01:15:00 | O26: ="LIM-"&G25&"-LIM LA "&E25&" ("&LEFT(H25,5)&"-"&LEFT(I25,5)&" hrs) / LA "&E26&" ("&LEFT(H26,5)&"-"&LEFT(I26,5)&" hrs)"
J27: PSV total: | K27: =TEXT(TIMEVALUE(I26)-TIMEVALUE(H23)+(I26<H23),"[h]:mm")
B29: Pairing ID | C29: FECHA REAL | D29: Day of Week | E29: Flight No | F29: Dep Stn | G29: Arr Stn | H29: STD | I29: STA | J29: subflota | K29: Conexion | L29: HBT
B30: 128 | C30: 01/09/2026 | D30: martes | E30: 2299 | F30: LIM | G30: CJA | H30: 11:35:00 | I30: 12:55:00 | J30: 320 | L30: 01:20:00 | M30: Sebastian Correa | N30: Tripulante Ejemplo 12, Tripulante Ejemplo 13, Tripulante Ejemplo 14, Tripulante Ejemplo 15 | O30: Reentrenamiento A320F | Q30: =B30 | R30: =C30 | S30: =D30 | T30: =E30&"/"&E31 | U30: =F30&"-"&G30&"-"&F30 | V30: =IF($M$30="","",$M$30) | W30: =IF($O$30="","",$O$30) | X30: =J30
B31: 128 | C31: 01/09/2026 | D31: martes | E31: 2298 | F31: CJA | G31: LIM | H31: 13:40:00 | I31: 14:50:00 | J31: 320 | K31: =TEXT(TIMEVALUE(H31)-TIMEVALUE(I30)+(TIMEVALUE(H31)<TIMEVALUE(I30)),"[h]:mm") | L31: 01:10:00 | O31: ="LIM-"&G30&"-LIM LA "&E30&" ("&LEFT(H30,5)&"-"&LEFT(I30,5)&" hrs) / LA "&E31&" ("&LEFT(H31,5)&"-"&LEFT(I31,5)&" hrs)"
J32: PSV total: | K32: =TEXT(TIMEVALUE(I31)-TIMEVALUE(H30)+(I31<H30),"[h]:mm")
B34: Pairing ID | C34: FECHA REAL | D34: Day of Week | E34: Flight No | F34: Dep Stn | G34: Arr Stn | H34: STD | I34: STA | J34: subflota | K34: Conexion | L34: HBT
B35: 130 | C35: 01/09/2026 | D35: martes | E35: 2111 | F35: LIM | G35: AQP | H35: 11:40:00 | I35: 13:10:00 | J35: 319 | L35: 01:30:00 | M35: Claudia Flores | N35: Tripulante Ejemplo 16, Tripulante Ejemplo 17, Tripulante Ejemplo 18 | O35: LCK A320F | Q35: =B35 | R35: =C35 | S35: =D35 | T35: =E35&"/"&E36 | U35: =F35&"-"&G35&"-"&F35 | V35: =IF($M$35="","",$M$35) | W35: =IF($O$35="","",$O$35) | X35: =J35
B36: 130 | C36: 01/09/2026 | D36: martes | E36: 2110 | F36: AQP | G36: LIM | H36: 14:00:00 | I36: 15:40:00 | J36: 319 | K36: =TEXT(TIMEVALUE(H36)-TIMEVALUE(I35)+(TIMEVALUE(H36)<TIMEVALUE(I35)),"[h]:mm") | L36: 01:40:00 | O36: ="LIM-"&G35&"-LIM LA "&E35&" ("&LEFT(H35,5)&"-"&LEFT(I35,5)&" hrs) / LA "&E36&" ("&LEFT(H36,5)&"-"&LEFT(I36,5)&" hrs)"
B37: 155 | C37: 01/09/2026 | D37: martes | E37: 2276 | F37: LIM | G37: CUZ | H37: 16:35:00 | I37: 17:55:00 | J37: 320 | K37: =TEXT(TIMEVALUE(H37)-TIMEVALUE(I36)+(TIMEVALUE(H37)<TIMEVALUE(I36)),"[h]:mm") | L37: 01:20:00 | M37: =IF($M$35="","",$M$35) | O37: =IF($O$35="","",$O$35) | Q37: =B37 | R37: =C37 | S37: =D37 | T37: =E37&"/"&E38 | U37: =F37&"-"&G37&"-"&F37 | V37: =IF($M$35="","",$M$35) | W37: =IF($O$35="","",$O$35) | X37: =J37
B38: 155 | C38: 01/09/2026 | D38: martes | E38: 2277 | F38: CUZ | G38: LIM | H38: 18:50:00 | I38: 20:25:00 | J38: 320 | K38: =TEXT(TIMEVALUE(H38)-TIMEVALUE(I37)+(TIMEVALUE(H38)<TIMEVALUE(I37)),"[h]:mm") | L38: 01:35:00 | O38: ="LIM-"&G37&"-LIM LA "&E37&" ("&LEFT(H37,5)&"-"&LEFT(I37,5)&" hrs) / LA "&E38&" ("&LEFT(H38,5)&"-"&LEFT(I38,5)&" hrs)"
J39: PSV total: | K39: =TEXT(TIMEVALUE(I38)-TIMEVALUE(H35)+(I38<H35),"[h]:mm")
B41: Pairing ID | C41: FECHA REAL | D41: Day of Week | E41: Flight No | F41: Dep Stn | G41: Arr Stn | H41: STD | I41: STA | J41: subflota | K41: Conexion | L41: HBT
B42: 133 | C42: 01/09/2026 | D42: martes | E42: 2023 | F42: LIM | G42: PEM | H42: 12:15:00 | I42: 13:55:00 | J42: 320 | L42: 01:40:00 | M42: Javier Zapata | N42: Tripulante Ejemplo 19, Tripulante Ejemplo 20, Tripulante Ejemplo 21, Tripulante Ejemplo 22 | O42: Reentrenamiento A320F | Q42: =B42 | R42: =C42 | S42: =D42 | T42: =E42&"/"&E43 | U42: =F42&"-"&G42&"-"&F42 | V42: =IF($M$42="","",$M$42) | W42: =IF($O$42="","",$O$42) | X42: =J42
B43: 133 | C43: 01/09/2026 | D43: martes | E43: 2024 | F43: PEM | G43: LIM | H43: 14:35:00 | I43: 16:10:00 | J43: 320 | K43: =TEXT(TIMEVALUE(H43)-TIMEVALUE(I42)+(TIMEVALUE(H43)<TIMEVALUE(I42)),"[h]:mm") | L43: 01:35:00 | O43: ="LIM-"&G42&"-LIM LA "&E42&" ("&LEFT(H42,5)&"-"&LEFT(I42,5)&" hrs) / LA "&E43&" ("&LEFT(H43,5)&"-"&LEFT(I43,5)&" hrs)"
B44: 157 | C44: 01/09/2026 | D44: martes | E44: 2213 | F44: LIM | G44: CIX | H44: 17:20:00 | I44: 18:50:00 | J44: 320 | K44: =TEXT(TIMEVALUE(H44)-TIMEVALUE(I43)+(TIMEVALUE(H44)<TIMEVALUE(I43)),"[h]:mm") | L44: 01:30:00 | M44: =IF($M$42="","",$M$42) | O44: =IF($O$42="","",$O$42) | Q44: =B44 | R44: =C44 | S44: =D44 | T44: =E44&"/"&E45 | U44: =F44&"-"&G44&"-"&F44 | V44: =IF($M$42="","",$M$42) | W44: =IF($O$42="","",$O$42) | X44: =J44
B45: 157 | C45: 01/09/2026 | D45: martes | E45: 2214 | F45: CIX | G45: LIM | H45: 19:25:00 | I45: 20:40:00 | J45: 320 | K45: =TEXT(TIMEVALUE(H45)-TIMEVALUE(I44)+(TIMEVALUE(H45)<TIMEVALUE(I44)),"[h]:mm") | L45: 01:15:00 | O45: ="LIM-"&G44&"-LIM LA "&E44&" ("&LEFT(H44,5)&"-"&LEFT(I44,5)&" hrs) / LA "&E45&" ("&LEFT(H45,5)&"-"&LEFT(I45,5)&" hrs)"
J46: PSV total: | K46: =TEXT(TIMEVALUE(I45)-TIMEVALUE(H42)+(I45<H42),"[h]:mm")
B48: Pairing ID | C48: FECHA REAL | D48: Day of Week | E48: Flight No | F48: Dep Stn | G48: Arr Stn | H48: STD | I48: STA | J48: subflota | K48: Conexion | L48: HBT
B49: 140 | C49: 01/09/2026 | D49: martes | E49: 2234 | F49: LIM | G49: IQT | H49: 13:35:00 | I49: 15:25:00 | J49: 320 | L49: 01:50:00 | M49: Jazmin Guerra | N49: Tripulante Ejemplo 23, Tripulante Ejemplo 24, Tripulante Ejemplo 25, Tripulante Ejemplo 26 | O49: LCK A320F | Q49: =B49 | R49: =C49 | S49: =D49 | T49: =E49&"/"&E50 | U49: =F49&"-"&G49&"-"&F49 | V49: =IF($M$49="","",$M$49) | W49: =IF($O$49="","",$O$49) | X49: =J49
...

Sheet Instructores
A1: Instructor | B1: BP | C1: Nombre | D1: Grupo
A2: Christian Rondon | B2: 1271571 | C2: RONDON BARRUTIA CHRISTIAN ERIC | D2: Grupo 1
A3: Erika Davila | B3: 967092 | C3: DAVILA BELLO MARIA ERIKA
A4: Sebastian Correa | B4: 2396710 | C4: CORREA GARCIA JUAN SEBASTIAN | D4: Grupo 1
A5: Fiorella Ruiz | B5: 2713993 | C5: RUIZ RIOJA FIORELLA DEL PILAR | D5: Grupo 1
A6: Jazmin Guerra | B6: 29530 | C6: GUERRA SUAREZ JAZMIN | D6: Grupo 2
A7: Jennifert Acurio | B7: 3779550 | C7: ACURIO DARGENT JENNIFERT MILAGROS | D7: Grupo 2
A8: Karen Santa Cruz | B8: 2843319 | C8: SANTA CRUZ HUAMAN KAREN | D8: Grupo 3
A9: Luis Bacigalupo | B9: 2963161 | C9: BACIGALUPO FLORES LUIS ENRIQUE
A10: Claudia Flores | B10: 3217561 | C10: FLORES FUENTES DAVILA CLAUDIA ALEXANDRA | D10: Grupo 2
A11: Karla Moz | B11: 71348 | C11: MOZ MONTES KARLA LISSETTE
A12: Elizabeth Torres | B12: 2369641 | C12: TORRES POLO ELIZABETH DEL PILAR
A13: Patricia Najar | B13: 2369624 | C13: NAJAR CRUZ PATRICIA DEL PILAR | D13: Grupo 3
A14: Javier Zapata | B14: 3134911 | C14: ZAPATA GARAYAR JAVIER RICARDO SALVADOR | D14: Grupo 2
A15: Jefferson Mendez | B15: 3750335 | C15: MENDEZ RUCOBA JEFFERSON | D15: Grupo 1
A16: Gabriela Ungaro | B16: 3852423 | C16: UNGARO GUTIERREZ GABRIELA | D16: Grupo 3
A17: Mariella Carrasco | B17: 2604360 | C17: CARRASCO BENAVIDES ROSA MARIELLA
A18: Cesar Campos | B18: 2823133 | C18: CAMPOS CONCHE CESAR AUGUSTO
A19: Kevin Segovia | B19: 3189967 | C19: SEGOVIA TAPIA RAY KEVIN
A20: Milagros Salas | B20: 2415373 | C20: SALAS COSIO MILAGROS PATRICIA
A21: Judith Fernandez | B21: 2440915 | C21: FERNANDEZ GARCIA JUDITH JULIET
A22: Rafael Nieto | B22: 3796947 | C22: NIETO SAENZ RAFAEL ANTONIO
A23: Gianfranco Celiz | B23: 3841387 | C23: CELIZ ROSSI GIANFRANCO PAOLO

Sheet Resumen Final
A1: TRIP | B1: Fecha | C1: DíaSEM | D1: Vuelo | E1: Ruta | F1: BP INS | G1: INS | H1: GRUPO INS | I1: ACTIVIDAD | J1: FLOTA | K1: Nombre INS | L1: CUPOS | M1: TRIPULANTES (cupo, SIMULADO)
A2: ='Pairings NB'!B9 | B2: ='Pairings NB'!C9 | C2: ='Pairings NB'!D9 | D2: ='Pairings NB'!E9&"/"&'Pairings NB'!E10 | E2: ='Pairings NB'!F9&"-"&'Pairings NB'!G9&"-"&'Pairings NB'!F9 | F2: =IFERROR(VLOOKUP('Pairings NB'!$M$9,Instructores!$A:$D,2,FALSE),"") | G2: ='Pairings NB'!$M$9 | H2: =IFERROR(VLOOKUP('Pairings NB'!$M$9,Instructores!$A:$D,4,FALSE),"") | I2: ='Pairings NB'!$O$9 | J2: ='Pairings NB'!J9 | K2: =IFERROR(VLOOKUP('Pairings NB'!$M$9,Instructores!$A:$D,3,FALSE),"") | L2: =IF('Pairings NB'!J9=320,4,3) | M2: ='Pairings NB'!$N$9
A3: ='Pairings NB'!B11 | B3: ='Pairings NB'!C11 | C3: ='Pairings NB'!D11 | D3: ='Pairings NB'!E11&"/"&'Pairings NB'!E12 | E3: ='Pairings NB'!F11&"-"&'Pairings NB'!G11&"-"&'Pairings NB'!F11 | F3: =IFERROR(VLOOKUP('Pairings NB'!$M$9,Instructores!$A:$D,2,FALSE),"") | G3: ='Pairings NB'!$M$9 | H3: =IFERROR(VLOOKUP('Pairings NB'!$M$9,Instructores!$A:$D,4,FALSE),"") | I3: ='Pairings NB'!$O$9 | J3: ='Pairings NB'!J11 | K3: =IFERROR(VLOOKUP('Pairings NB'!$M$9,Instructores!$A:$D,3,FALSE),"") | L3: =IF('Pairings NB'!J11=320,4,3) | M3: ='Pairings NB'!$N$9
A4: ='Pairings NB'!B16 | B4: ='Pairings NB'!C16 | C4: ='Pairings NB'!D16 | D4: ='Pairings NB'!E16&"/"&'Pairings NB'!E17 | E4: ='Pairings NB'!F16&"-"&'Pairings NB'!G16&"-"&'Pairings NB'!F16 | F4: =IFERROR(VLOOKUP('Pairings NB'!$M$16,Instructores!$A:$D,2,FALSE),"") | G4: ='Pairings NB'!$M$16 | H4: =IFERROR(VLOOKUP('Pairings NB'!$M$16,Instructores!$A:$D,4,FALSE),"") | I4: ='Pairings NB'!$O$16 | J4: ='Pairings NB'!J16 | K4: =IFERROR(VLOOKUP('Pairings NB'!$M$16,Instructores!$A:$D,3,FALSE),"") | L4: =IF('Pairings NB'!J16=320,4,3) | M4: ='Pairings NB'!$N$16
A5: ='Pairings NB'!B18 | B5: ='Pairings NB'!C18 | C5: ='Pairings NB'!D18 | D5: ='Pairings NB'!E18&"/"&'Pairings NB'!E19 | E5: ='Pairings NB'!F18&"-"&'Pairings NB'!G18&"-"&'Pairings NB'!F18 | F5: =IFERROR(VLOOKUP('Pairings NB'!$M$16,Instructores!$A:$D,2,FALSE),"") | G5: ='Pairings NB'!$M$16 | H5: =IFERROR(VLOOKUP('Pairings NB'!$M$16,Instructores!$A:$D,4,FALSE),"") | I5: ='Pairings NB'!$O$16 | J5: ='Pairings NB'!J18 | K5: =IFERROR(VLOOKUP('Pairings NB'!$M$16,Instructores!$A:$D,3,FALSE),"") | L5: =IF('Pairings NB'!J18=320,4,3) | M5: ='Pairings NB'!$N$16
A6: ='Pairings NB'!B23 | B6: ='Pairings NB'!C23 | C6: ='Pairings NB'!D23 | D6: ='Pairings NB'!E23&"/"&'Pairings NB'!E24 | E6: ='Pairings NB'!F23&"-"&'Pairings NB'!G23&"-"&'Pairings NB'!F23 | F6: =IFERROR(VLOOKUP('Pairings NB'!$M$23,Instructores!$A:$D,2,FALSE),"") | G6: ='Pairings NB'!$M$23 | H6: =IFERROR(VLOOKUP('Pairings NB'!$M$23,Instructores!$A:$D,4,FALSE),"") | I6: ='Pairings NB'!$O$23 | J6: ='Pairings NB'!J23 | K6: =IFERROR(VLOOKUP('Pairings NB'!$M$23,Instructores!$A:$D,3,FALSE),"") | L6: =IF('Pairings NB'!J23=320,4,3) | M6: ='Pairings NB'!$N$23
A7: ='Pairings NB'!B25 | B7: ='Pairings NB'!C25 | C7: ='Pairings NB'!D25 | D7: ='Pairings NB'!E25&"/"&'Pairings NB'!E26 | E7: ='Pairings NB'!F25&"-"&'Pairings NB'!G25&"-"&'Pairings NB'!F25 | F7: =IFERROR(VLOOKUP('Pairings NB'!$M$23,Instructores!$A:$D,2,FALSE),"") | G7: ='Pairings NB'!$M$23 | H7: =IFERROR(VLOOKUP('Pairings NB'!$M$23,Instructores!$A:$D,4,FALSE),"") | I7: ='Pairings NB'!$O$23 | J7: ='Pairings NB'!J25 | K7: =IFERROR(VLOOKUP('Pairings NB'!$M$23,Instructores!$A:$D,3,FALSE),"") | L7: =IF('Pairings NB'!J25=320,4,3) | M7: ='Pairings NB'!$N$23
A8: ='Pairings NB'!B30 | B8: ='Pairings NB'!C30 | C8: ='Pairings NB'!D30 | D8: ='Pairings NB'!E30&"/"&'Pairings NB'!E31 | E8: ='Pairings NB'!F30&"-"&'Pairings NB'!G30&"-"&'Pairings NB'!F30 | F8: =IFERROR(VLOOKUP('Pairings NB'!$M$30,Instructores!$A:$D,2,FALSE),"") | G8: ='Pairings NB'!$M$30 | H8: =IFERROR(VLOOKUP('Pairings NB'!$M$30,Instructores!$A:$D,4,FALSE),"") | I8: ='Pairings NB'!$O$30 | J8: ='Pairings NB'!J30 | K8: =IFERROR(VLOOKUP('Pairings NB'!$M$30,Instructores!$A:$D,3,FALSE),"") | L8: =IF('Pairings NB'!J30=320,4,3) | M8: ='Pairings NB'!$N$30
A9: ='Pairings NB'!B35 | B9: ='Pairings NB'!C35 | C9: ='Pairings NB'!D35 | D9: ='Pairings NB'!E35&"/"&'Pairings NB'!E36 | E9: ='Pairings NB'!F35&"-"&'Pairings NB'!G35&"-"&'Pairings NB'!F35 | F9: =IFERROR(VLOOKUP('Pairings NB'!$M$35,Instructores!$A:$D,2,FALSE),"") | G9: ='Pairings NB'!$M$35 | H9: =IFERROR(VLOOKUP('Pairings NB'!$M$35,Instructores!$A:$D,4,FALSE),"") | I9: ='Pairings NB'!$O$35 | J9: ='Pairings NB'!J35 | K9: =IFERROR(VLOOKUP('Pairings NB'!$M$35,Instructores!$A:$D,3,FALSE),"") | L9: =IF('Pairings NB'!J35=320,4,3) | M9: ='Pairings NB'!$N$35
A10: ='Pairings NB'!B37 | B10: ='Pairings NB'!C37 | C10: ='Pairings NB'!D37 | D10: ='Pairings NB'!E37&"/"&'Pairings NB'!E38 | E10: ='Pairings NB'!F37&"-"&'Pairings NB'!G37&"-"&'Pairings NB'!F37 | F10: =IFERROR(VLOOKUP('Pairings NB'!$M$35,Instructores!$A:$D,2,FALSE),"") | G10: ='Pairings NB'!$M$35 | H10: =IFERROR(VLOOKUP('Pairings NB'!$M$35,Instructores!$A:$D,4,FALSE),"") | I10: ='Pairings NB'!$O$35 | J10: ='Pairings NB'!J37 | K10: =IFERROR(VLOOKUP('Pairings NB'!$M$35,Instructores!$A:$D,3,FALSE),"") | L10: =IF('Pairings NB'!J37=320,4,3) | M10: ='Pairings NB'!$N$35
A11: ='Pairings NB'!B42 | B11: ='Pairings NB'!C42 | C11: ='Pairings NB'!D42 | D11: ='Pairings NB'!E42&"/"&'Pairings NB'!E43 | E11: ='Pairings NB'!F42&"-"&'Pairings NB'!G42&"-"&'Pairings NB'!F42 | F11: =IFERROR(VLOOKUP('Pairings NB'!$M$42,Instructores!$A:$D,2,FALSE),"") | G11: ='Pairings NB'!$M$42 | H11: =IFERROR(VLOOKUP('Pairings NB'!$M$42,Instructores!$A:$D,4,FALSE),"") | I11: ='Pairings NB'!$O$42 | J11: ='Pairings NB'!J42 | K11: =IFERROR(VLOOKUP('Pairings NB'!$M$42,Instructores!$A:$D,3,FALSE),"") | L11: =IF('Pairings NB'!J42=320,4,3) | M11: ='Pairings NB'!$N$42
A12: ='Pairings NB'!B44 | B12: ='Pairings NB'!C44 | C12: ='Pairings NB'!D44 | D12: ='Pairings NB'!E44&"/"&'Pairings NB'!E45 | E12: ='Pairings NB'!F44&"-"&'Pairings NB'!G44&"-"&'Pairings NB'!F44 | F12: =IFERROR(VLOOKUP('Pairings NB'!$M$42,Instructores!$A:$D,2,FALSE),"") | G12: ='Pairings NB'!$M$42 | H12: =IFERROR(VLOOKUP('Pairings NB'!$M$42,Instructores!$A:$D,4,FALSE),"") | I12: ='Pairings NB'!$O$42 | J12: ='Pairings NB'!J44 | K12: =IFERROR(VLOOKUP('Pairings NB'!$M$42,Instructores!$A:$D,3,FALSE),"") | L12: =IF('Pairings NB'!J44=320,4,3) | M12: ='Pairings NB'!$N$42
A13: ='Pairings NB'!B49 | B13: ='Pairings NB'!C49 | C13: ='Pairings NB'!D49 | D13: ='Pairings NB'!E49&"/"&'Pairings NB'!E50 | E13: ='Pairings NB'!F49&"-"&'Pairings NB'!G49&"-"&'Pairings NB'!F49 | F13: =IFERROR(VLOOKUP('Pairings NB'!$M$49,Instructores!$A:$D,2,FALSE),"") | G13: ='Pairings NB'!$M$49 | H13: =IFERROR(VLOOKUP('Pairings NB'!$M$49,Instructores!$A:$D,4,FALSE),"") | I13: ='Pairings NB'!$O$49 | J13: ='Pairings NB'!J49 | K13: =IFERROR(VLOOKUP('Pairings NB'!$M$49,Instructores!$A:$D,3,FALSE),"") | L13: =IF('Pairings NB'!J49=320,4,3) | M13: ='Pairings NB'!$N$49
A14: ='Pairings NB'!B54 | B14: ='Pairings NB'!C54 | C14: ='Pairings NB'!D54 | D14: ='Pairings NB'!E54&"/"&'Pairings NB'!E55 | E14: ='Pairings NB'!F54&"-"&'Pairings NB'!G54&"-"&'Pairings NB'!F54 | F14: =IFERROR(VLOOKUP('Pairings NB'!$M$54,Instructores!$A:$D,2,FALSE),"") | G14: ='Pairings NB'!$M$54 | H14: =IFERROR(VLOOKUP('Pairings NB'!$M$54,Instructores!$A:$D,4,FALSE),"") | I14: ='Pairings NB'!$O$54 | J14: ='Pairings NB'!J54 | K14: =IFERROR(VLOOKUP('Pairings NB'!$M$54,Instructores!$A:$D,3,FALSE),"") | L14: =IF('Pairings NB'!J54=320,4,3) | M14: ='Pairings NB'!$N$54
A15: ='Pairings NB'!B59 | B15: ='Pairings NB'!C59 | C15: ='Pairings NB'!D59 | D15: ='Pairings NB'!E59&"/"&'Pairings NB'!E60 | E15: ='Pairings NB'!F59&"-"&'Pairings NB'!G59&"-"&'Pairings NB'!F59 | F15: =IFERROR(VLOOKUP('Pairings NB'!$M$59,Instructores!$A:$D,2,FALSE),"") | G15: ='Pairings NB'!$M$59 | H15: =IFERROR(VLOOKUP('Pairings NB'!$M$59,Instructores!$A:$D,4,FALSE),"") | I15: ='Pairings NB'!$O$59 | J15: ='Pairings NB'!J59 | K15: =IFERROR(VLOOKUP('Pairings NB'!$M$59,Instructores!$A:$D,3,FALSE),"") | L15: =IF('Pairings NB'!J59=320,4,3) | M15: ='Pairings NB'!$N$59
A16: ='Pairings NB'!B64 | B16: ='Pairings NB'!C64 | C16: ='Pairings NB'!D64 | D16: ='Pairings NB'!E64&"/"&'Pairings NB'!E65 | E16: ='Pairings NB'!F64&"-"&'Pairings NB'!G64&"-"&'Pairings NB'!F64 | F16: =IFERROR(VLOOKUP('Pairings NB'!$M$64,Instructores!$A:$D,2,FALSE),"") | G16: ='Pairings NB'!$M$64 | H16: =IFERROR(VLOOKUP('Pairings NB'!$M$64,Instructores!$A:$D,4,FALSE),"") | I16: ='Pairings NB'!$O$64 | J16: ='Pairings NB'!J64 | K16: =IFERROR(VLOOKUP('Pairings NB'!$M$64,Instructores!$A:$D,3,FALSE),"") | L16: =IF('Pairings NB'!J64=320,4,3) | M16: ='Pairings NB'!$N$64
A17: ='Pairings NB'!B69 | B17: ='Pairings NB'!C69 | C17: ='Pairings NB'!D69 | D17: ='Pairings NB'!E69&"/"&'Pairings NB'!E70 | E17: ='Pairings NB'!F69&"-"&'Pairings NB'!G69&"-"&'Pairings NB'!F69 | F17: =IFERROR(VLOOKUP('Pairings NB'!$M$69,Instructores!$A:$D,2,FALSE),"") | G17: ='Pairings NB'!$M$69 | H17: =IFERROR(VLOOKUP('Pairings NB'!$M$69,Instructores!$A:$D,4,FALSE),"") | I17: ='Pairings NB'!$O$69 | J17: ='Pairings NB'!J69 | K17: =IFERROR(VLOOKUP('Pairings NB'!$M$69,Instructores!$A:$D,3,FALSE),"") | L17: =IF('Pairings NB'!J69=320,4,3) | M17: ='Pairings NB'!$N$69
A18: ='Pairings NB'!B74 | B18: ='Pairings NB'!C74 | C18: ='Pairings NB'!D74 | D18: ='Pairings NB'!E74&"/"&'Pairings NB'!E75 | E18: ='Pairings NB'!F74&"-"&'Pairings NB'!G74&"-"&'Pairings NB'!F74 | F18: =IFERROR(VLOOKUP('Pairings NB'!$M$74,Instructores!$A:$D,2,FALSE),"") | G18: ='Pairings NB'!$M$74 | H18: =IFERROR(VLOOKUP('Pairings NB'!$M$74,Instructores!$A:$D,4,FALSE),"") | I18: ='Pairings NB'!$O$74 | J18: ='Pairings NB'!J74 | K18: =IFERROR(VLOOKUP('Pairings NB'!$M$74,Instructores!$A:$D,3,FALSE),"") | L18: =IF('Pairings NB'!J74=320,4,3) | M18: ='Pairings NB'!$N$74
A19: ='Pairings NB'!B79 | B19: ='Pairings NB'!C79 | C19: ='Pairings NB'!D79 | D19: ='Pairings NB'!E79&"/"&'Pairings NB'!E80 | E19: ='Pairings NB'!F79&"-"&'Pairings NB'!G79&"-"&'Pairings NB'!F79 | F19: =IFERROR(VLOOKUP('Pairings NB'!$M$79,Instructores!$A:$D,2,FALSE),"") | G19: ='Pairings NB'!$M$79 | H19: =IFERROR(VLOOKUP('Pairings NB'!$M$79,Instructores!$A:$D,4,FALSE),"") | I19: ='Pairings NB'!$O$79 | J19: ='Pairings NB'!J79 | K19: =IFERROR(VLOOKUP('Pairings NB'!$M$79,Instructores!$A:$D,3,FALSE),"") | L19: =IF('Pairings NB'!J79=320,4,3) | M19: ='Pairings NB'!$N$79
A20: ='Pairings NB'!B84 | B20: ='Pairings NB'!C84 | C20: ='Pairings NB'!D84 | D20: ='Pairings NB'!E84&"/"&'Pairings NB'!E85 | E20: ='Pairings NB'!F84&"-"&'Pairings NB'!G84&"-"&'Pairings NB'!F84 | F20: =IFERROR(VLOOKUP('Pairings NB'!$M$84,Instructores!$A:$D,2,FALSE),"") | G20: ='Pairings NB'!$M$84 | H20: =IFERROR(VLOOKUP('Pairings NB'!$M$84,Instructores!$A:$D,4,FALSE),"") | I20: ='Pairings NB'!$O$84 | J20: ='Pairings NB'!J84 | K20: =IFERROR(VLOOKUP('Pairings NB'!$M$84,Instructores!$A:$D,3,FALSE),"") | L20: =IF('Pairings NB'!J84=320,4,3) | M20: ='Pairings NB'!$N$84
A21: ='Pairings NB'!B89 | B21: ='Pairings NB'!C89 | C21: ='Pairings NB'!D89 | D21: ='Pairings NB'!E89&"/"&'Pairings NB'!E90 | E21: ='Pairings NB'!F89&"-"&'Pairings NB'!G89&"-"&'Pairings NB'!F89 | F21: =IFERROR(VLOOKUP('Pairings NB'!$M$89,Instructores!$A:$D,2,FALSE),"") | G21: ='Pairings NB'!$M$89 | H21: =IFERROR(VLOOKUP('Pairings NB'!$M$89,Instructores!$A:$D,4,FALSE),"") | I21: ='Pairings NB'!$O$89 | J21: ='Pairings NB'!J89 | K21: =IFERROR(VLOOKUP('Pairings NB'!$M$89,Instructores!$A:$D,3,FALSE),"") | L21: =IF('Pairings NB'!J89=320,4,3) | M21: ='Pairings NB'!$N$89
A22: ='Pairings NB'!B94 | B22: ='Pairings NB'!C94 | C22: ='Pairings NB'!D94 | D22: ='Pairings NB'!E94&"/"&'Pairings NB'!E95 | E22: ='Pairings NB'!F94&"-"&'Pairings NB'!G94&"-"&'Pairings NB'!F94 | F22: =IFERROR(VLOOKUP('Pairings NB'!$M$94,Instructores!$A:$D,2,FALSE),"") | G22: ='Pairings NB'!$M$94 | H22: =IFERROR(VLOOKUP('Pairings NB'!$M$94,Instructores!$A:$D,4,FALSE),"") | I22: ='Pairings NB'!$O$94 | J22: ='Pairings NB'!J94 | K22: =IFERROR(VLOOKUP('Pairings NB'!$M$94,Instructores!$A:$D,3,FALSE),"") | L22: =IF('Pairings NB'!J94=320,4,3) | M22: ='Pairings NB'!$N$94
A23: ='Pairings NB'!B99 | B23: ='Pairings NB'!C99 | C23: ='Pairings NB'!D99 | D23: ='Pairings NB'!E99&"/"&'Pairings NB'!E100 | E23: ='Pairings NB'!F99&"-"&'Pairings NB'!G99&"-"&'Pairings NB'!F99 | F23: =IFERROR(VLOOKUP('Pairings NB'!$M$99,Instructores!$A:$D,2,FALSE),"") | G23: ='Pairings NB'!$M$99 | H23: =IFERROR(VLOOKUP('Pairings NB'!$M$99,Instructores!$A:$D,4,FALSE),"") | I23: ='Pairings NB'!$O$99 | J23: ='Pairings NB'!J99 | K23: =IFERROR(VLOOKUP('Pairings NB'!$M$99,Instructores!$A:$D,3,FALSE),"") | L23: =IF('Pairings NB'!J99=320,4,3) | M23: ='Pairings NB'!$N$99
A24: ='Pairings NB'!B101 | B24: ='Pairings NB'!C101 | C24: ='Pairings NB'!D101 | D24: ='Pairings NB'!E101&"/"&'Pairings NB'!E102 | E24: ='Pairings NB'!F101&"-"&'Pairings NB'!G101&"-"&'Pairings NB'!F101 | F24: =IFERROR(VLOOKUP('Pairings NB'!$M$99,Instructores!$A:$D,2,FALSE),"") | G24: ='Pairings NB'!$M$99 | H24: =IFERROR(VLOOKUP('Pairings NB'!$M$99,Instructores!$A:$D,4,FALSE),"") | I24: ='Pairings NB'!$O$99 | J24: ='Pairings NB'!J101 | K24: =IFERROR(VLOOKUP('Pairings NB'!$M$99,Instructores!$A:$D,3,FALSE),"") | L24: =IF('Pairings NB'!J101=320,4,3) | M24: ='Pairings NB'!$N$99
A25: ='Pairings NB'!B106 | B25: ='Pairings NB'!C106 | C25: ='Pairings NB'!D106 | D25: ='Pairings NB'!E106&"/"&'Pairings NB'!E107 | E25: ='Pairings NB'!F106&"-"&'Pairings NB'!G106&"-"&'Pairings NB'!F106 | F25: =IFERROR(VLOOKUP('Pairings NB'!$M$106,Instructores!$A:$D,2,FALSE),"") | G25: ='Pairings NB'!$M$106 | H25: =IFERROR(VLOOKUP('Pairings NB'!$M$106,Instructores!$A:$D,4,FALSE),"") | I25: ='Pairings NB'!$O$106 | J25: ='Pairings NB'!J106 | K25: =IFERROR(VLOOKUP('Pairings NB'!$M$106,Instructores!$A:$D,3,FALSE),"") | L25: =IF('Pairings NB'!J106=320,4,3) | M25: ='Pairings NB'!$N$106
A26: ='Pairings NB'!B111 | B26: ='Pairings NB'!C111 | C26: ='Pairings NB'!D111 | D26: ='Pairings NB'!E111&"/"&'Pairings NB'!E112 | E26: ='Pairings NB'!F111&"-"&'Pairings NB'!G111&"-"&'Pairings NB'!F111 | F26: =IFERROR(VLOOKUP('Pairings NB'!$M$111,Instructores!$A:$D,2,FALSE),"") | G26: ='Pairings NB'!$M$111 | H26: =IFERROR(VLOOKUP('Pairings NB'!$M$111,Instructores!$A:$D,4,FALSE),"") | I26: ='Pairings NB'!$O$111 | J26: ='Pairings NB'!J111 | K26: =IFERROR(VLOOKUP('Pairings NB'!$M$111,Instructores!$A:$D,3,FALSE),"") | L26: =IF('Pairings NB'!J111=320,4,3) | M26: ='Pairings NB'!$N$111
A27: ='Pairings NB'!B116 | B27: ='Pairings NB'!C116 | C27: ='Pairings NB'!D116 | D27: ='Pairings NB'!E116&"/"&'Pairings NB'!E117 | E27: ='Pairings NB'!F116&"-"&'Pairings NB'!G116&"-"&'Pairings NB'!F116 | F27: =IFERROR(VLOOKUP('Pairings NB'!$M$116,Instructores!$A:$D,2,FALSE),"") | G27: ='Pairings NB'!$M$116 | H27: =IFERROR(VLOOKUP('Pairings NB'!$M$116,Instructores!$A:$D,4,FALSE),"") | I27: ='Pairings NB'!$O$116 | J27: ='Pairings NB'!J116 | K27: =IFERROR(VLOOKUP('Pairings NB'!$M$116,Instructores!$A:$D,3,FALSE),"") | L27: =IF('Pairings NB'!J116=320,4,3) | M27: ='Pairings NB'!$N$116
A28: ='Pairings NB'!B118 | B28: ='Pairings NB'!C118 | C28: ='Pairings NB'!D118 | D28: ='Pairings NB'!E118&"/"&'Pairings NB'!E119 | E28: ='Pairings NB'!F118&"-"&'Pairings NB'!G118&"-"&'Pairings NB'!F118 | F28: =IFERROR(VLOOKUP('Pairings NB'!$M$116,Instructores!$A:$D,2,FALSE),"") | G28: ='Pairings NB'!$M$116 | H28: =IFERROR(VLOOKUP('Pairings NB'!$M$116,Instructores!$A:$D,4,FALSE),"") | I28: ='Pairings NB'!$O$116 | J28: ='Pairings NB'!J118 | K28: =IFERROR(VLOOKUP('Pairings NB'!$M$116,Instructores!$A:$D,3,FALSE),"") | L28: =IF('Pairings NB'!J118=320,4,3) | M28: ='Pairings NB'!$N$116
A29: ='Pairings NB'!B123 | B29: ='Pairings NB'!C123 | C29: ='Pairings NB'!D123 | D29: ='Pairings NB'!E123&"/"&'Pairings NB'!E124 | E29: ='Pairings NB'!F123&"-"&'Pairings NB'!G123&"-"&'Pairings NB'!F123 | F29: =IFERROR(VLOOKUP('Pairings NB'!$M$123,Instructores!$A:$D,2,FALSE),"") | G29: ='Pairings NB'!$M$123 | H29: =IFERROR(VLOOKUP('Pairings NB'!$M$123,Instructores!$A:$D,4,FALSE),"") | I29: ='Pairings NB'!$O$123 | J29: ='Pairings NB'!J123 | K29: =IFERROR(VLOOKUP('Pairings NB'!$M$123,Instructores!$A:$D,3,FALSE),"") | L29: =IF('Pairings NB'!J123=320,4,3) | M29: ='Pairings NB'!$N$123
A30: ='Pairings NB'!B125 | B30: ='Pairings NB'!C125 | C30: ='Pairings NB'!D125 | D30: ='Pairings NB'!E125&"/"&'Pairings NB'!E126 | E30: ='Pairings NB'!F125&"-"&'Pairings NB'!G125&"-"&'Pairings NB'!F125 | F30: =IFERROR(VLOOKUP('Pairings NB'!$M$123,Instructores!$A:$D,2,FALSE),"") | G30: ='Pairings NB'!$M$123 | H30: =IFERROR(VLOOKUP('Pairings NB'!$M$123,Instructores!$A:$D,4,FALSE),"") | I30: ='Pairings NB'!$O$123 | J30: ='Pairings NB'!J125 | K30: =IFERROR(VLOOKUP('Pairings NB'!$M$123,Instructores!$A:$D,3,FALSE),"") | L30: =IF('Pairings NB'!J125=320,4,3) | M30: ='Pairings NB'!$N$123
A31: ='Pairings NB'!B130 | B31: ='Pairings NB'!C130 | C31: ='Pairings NB'!D130 | D31: ='Pairings NB'!E130&"/"&'Pairings NB'!E131 | E31: ='Pairings NB'!F130&"-"&'Pairings NB'!G130&"-"&'Pairings NB'!F130 | F31: =IFERROR(VLOOKUP('Pairings NB'!$M$130,Instructores!$A:$D,2,FALSE),"") | G31: ='Pairings NB'!$M$130 | H31: =IFERROR(VLOOKUP('Pairings NB'!$M$130,Instructores!$A:$D,4,FALSE),"") | I31: ='Pairings NB'!$O$130 | J31: ='Pairings NB'!J130 | K31: =IFERROR(VLOOKUP('Pairings NB'!$M$130,Instructores!$A:$D,3,FALSE),"") | L31: =IF('Pairings NB'!J130=320,4,3) | M31: ='Pairings NB'!$N$130
A32: ='Pairings NB'!B132 | B32: ='Pairings NB'!C132 | C32: ='Pairings NB'!D132 | D32: ='Pairings NB'!E132&"/"&'Pairings NB'!E133 | E32: ='Pairings NB'!F132&"-"&'Pairings NB'!G132&"-"&'Pairings NB'!F132 | F32: =IFERROR(VLOOKUP('Pairings NB'!$M$130,Instructores!$A:$D,2,FALSE),"") | G32: ='Pairings NB'!$M$130 | H32: =IFERROR(VLOOKUP('Pairings NB'!$M$130,Instructores!$A:$D,4,FALSE),"") | I32: ='Pairings NB'!$O$130 | J32: ='Pairings NB'!J132 | K32: =IFERROR(VLOOKUP('Pairings NB'!$M$130,Instructores!$A:$D,3,FALSE),"") | L32: =IF('Pairings NB'!J132=320,4,3) | M32: ='Pairings NB'!$N$130
A33: ='Pairings NB'!B137 | B33: ='Pairings NB'!C137 | C33: ='Pairings NB'!D137 | D33: ='Pairings NB'!E137&"/"&'Pairings NB'!E138 | E33: ='Pairings NB'!F137&"-"&'Pairings NB'!G137&"-"&'Pairings NB'!F137 | F33: =IFERROR(VLOOKUP('Pairings NB'!$M$137,Instructores!$A:$D,2,FALSE),"") | G33: ='Pairings NB'!$M$137 | H33: =IFERROR(VLOOKUP('Pairings NB'!$M$137,Instructores!$A:$D,4,FALSE),"") | I33: ='Pairings NB'!$O$137 | J33: ='Pairings NB'!J137 | K33: =IFERROR(VLOOKUP('Pairings NB'!$M$137,Instructores!$A:$D,3,FALSE),"") | L33: =IF('Pairings NB'!J137=320,4,3) | M33: ='Pairings NB'!$N$137
A34: ='Pairings NB'!B142 | B34: ='Pairings NB'!C142 | C34: ='Pairings NB'!D142 | D34: ='Pairings NB'!E142&"/"&'Pairings NB'!E143 | E34: ='Pairings NB'!F142&"-"&'Pairings NB'!G142&"-"&'Pairings NB'!F142 | F34: =IFERROR(VLOOKUP('Pairings NB'!$M$142,Instructores!$A:$D,2,FALSE),"") | G34: ='Pairings NB'!$M$142 | H34: =IFERROR(VLOOKUP('Pairings NB'!$M$142,Instructores!$A:$D,4,FALSE),"") | I34: ='Pairings NB'!$O$142 | J34: ='Pairings NB'!J142 | K34: =IFERROR(VLOOKUP('Pairings NB'!$M$142,Instructores!$A:$D,3,FALSE),"") | L34: =IF('Pairings NB'!J142=320,4,3) | M34: ='Pairings NB'!$N$142
A35: ='Pairings NB'!B147 | B35: ='Pairings NB'!C147 | C35: ='Pairings NB'!D147 | D35: ='Pairings NB'!E147&"/"&'Pairings NB'!E148 | E35: ='Pairings NB'!F147&"-"&'Pairings NB'!G147&"-"&'Pairings NB'!F147 | F35: =IFERROR(VLOOKUP('Pairings NB'!$M$147,Instructores!$A:$D,2,FALSE),"") | G35: ='Pairings NB'!$M$147 | H35: =IFERROR(VLOOKUP('Pairings NB'!$M$147,Instructores!$A:$D,4,FALSE),"") | I35: ='Pairings NB'!$O$147 | J35: ='Pairings NB'!J147 | K35: =IFERROR(VLOOKUP('Pairings NB'!$M$147,Instructores!$A:$D,3,FALSE),"") | L35: =IF('Pairings NB'!J147=320,4,3) | M35: ='Pairings NB'!$N$147
A36: ='Pairings NB'!B149 | B36: ='Pairings NB'!C149 | C36: ='Pairings NB'!D149 | D36: ='Pairings NB'!E149&"/"&'Pairings NB'!E150 | E36: ='Pairings NB'!F149&"-"&'Pairings NB'!G149&"-"&'Pairings NB'!F149 | F36: =IFERROR(VLOOKUP('Pairings NB'!$M$147,Instructores!$A:$D,2,FALSE),"") | G36: ='Pairings NB'!$M$147 | H36: =IFERROR(VLOOKUP('Pairings NB'!$M$147,Instructores!$A:$D,4,FALSE),"") | I36: ='Pairings NB'!$O$147 | J36: ='Pairings NB'!J149 | K36: =IFERROR(VLOOKUP('Pairings NB'!$M$147,Instructores!$A:$D,3,FALSE),"") | L36: =IF('Pairings NB'!J149=320,4,3) | M36: ='Pairings NB'!$N$147
A37: ='Pairings NB'!B154 | B37: ='Pairings NB'!C154 | C37: ='Pairings NB'!D154 | D37: ='Pairings NB'!E154&"/"&'Pairings NB'!E155 | E37: ='Pairings NB'!F154&"-"&'Pairings NB'!G154&"-"&'Pairings NB'!F154 | F37: =IFERROR(VLOOKUP('Pairings NB'!$M$154,Instructores!$A:$D,2,FALSE),"") | G37: ='Pairings NB'!$M$154 | H37: =IFERROR(VLOOKUP('Pairings NB'!$M$154,Instructores!$A:$D,4,FALSE),"") | I37: ='Pairings NB'!$O$154 | J37: ='Pairings NB'!J154 | K37: =IFERROR(VLOOKUP('Pairings NB'!$M$154,Instructores!$A:$D,3,FALSE),"") | L37: =IF('Pairings NB'!J154=320,4,3) | M37: ='Pairings NB'!$N$154
A38: ='Pairings NB'!B159 | B38: ='Pairings NB'!C159 | C38: ='Pairings NB'!D159 | D38: ='Pairings NB'!E159&"/"&'Pairings NB'!E160 | E38: ='Pairings NB'!F159&"-"&'Pairings NB'!G159&"-"&'Pairings NB'!F159 | F38: =IFERROR(VLOOKUP('Pairings NB'!$M$159,Instructores!$A:$D,2,FALSE),"") | G38: ='Pairings NB'!$M$159 | H38: =IFERROR(VLOOKUP('Pairings NB'!$M$159,Instructores!$A:$D,4,FALSE),"") | I38: ='Pairings NB'!$O$159 | J38: ='Pairings NB'!J159 | K38: =IFERROR(VLOOKUP('Pairings NB'!$M$159,Instructores!$A:$D,3,FALSE),"") | L38: =IF('Pairings NB'!J159=320,4,3) | M38: ='Pairings NB'!$N$159
A39: ='Pairings NB'!B164 | B39: ='Pairings NB'!C164 | C39: ='Pairings NB'!D164 | D39: ='Pairings NB'!E164&"/"&'Pairings NB'!E165 | E39: ='Pairings NB'!F164&"-"&'Pairings NB'!G164&"-"&'Pairings NB'!F164 | F39: =IFERROR(VLOOKUP('Pairings NB'!$M$164,Instructores!$A:$D,2,FALSE),"") | G39: ='Pairings NB'!$M$164 | H39: =IFERROR(VLOOKUP('Pairings NB'!$M$164,Instructores!$A:$D,4,FALSE),"") | I39: ='Pairings NB'!$O$164 | J39: ='Pairings NB'!J164 | K39: =IFERROR(VLOOKUP('Pairings NB'!$M$164,Instructores!$A:$D,3,FALSE),"") | L39: =IF('Pairings NB'!J164=320,4,3) | M39: ='Pairings NB'!$N$164
A40: ='Pairings NB'!B169 | B40: ='Pairings NB'!C169 | C40: ='Pairings NB'!D169 | D40: ='Pairings NB'!E169&"/"&'Pairings NB'!E170 | E40: ='Pairings NB'!F169&"-"&'Pairings NB'!G169&"-"&'Pairings NB'!F169 | F40: =IFERROR(VLOOKUP('Pairings NB'!$M$169,Instructores!$A:$D,2,FALSE),"") | G40: ='Pairings NB'!$M$169 | H40: =IFERROR(VLOOKUP('Pairings NB'!$M$169,Instructores!$A:$D,4,FALSE),"") | I40: ='Pairings NB'!$O$169 | J40: ='Pairings NB'!J169 | K40: =IFERROR(VLOOKUP('Pairings NB'!$M$169,Instructores!$A:$D,3,FALSE),"") | L40: =IF('Pairings NB'!J169=320,4,3) | M40: ='Pairings NB'!$N$169
...

Sheet Tripulantes (SIMULADO)
A1: *** DATOS FICTICIOS DE EJEMPLO — no son tripulantes reales. Generado para demostrar el automatismo de asignación. Reemplazar por el archivo real del roster del mes + historial de reva del mes anterior. ***
A2: BP (ficticio) | B2: CAT | C2: Nombre (ficticio) | D2: OBS FREEZE | E2: Reva mes anterior (INS, ficticio) | F2: Instructor asignado SET (simulado) | G2: Grupo INS asignado | H2: ¿Programado este bloque?
A3: 9000001 | B3: TCA | C3: Tripulante Ejemplo 01 | D3: LCK P1 | F3: Christian Rondon | G3: Grupo 1 | H3: SI
A4: 9000002 | B4: TCA | C4: Tripulante Ejemplo 02 | D4: LCK P1 | E4: Fiorella Ruiz | F4: Christian Rondon | G4: Grupo 1 | H4: SI
A5: 9000003 | B5: JSBA | C5: Tripulante Ejemplo 03 | D5: LCK P1 | F5: Christian Rondon | G5: Grupo 1 | H5: SI
A6: 9000004 | B6: TCA | C6: Tripulante Ejemplo 04 | D6: LCK P1 | E6: Sebastian Correa | F6: Christian Rondon | G6: Grupo 1 | H6: SI
A7: 9000005 | B7: JSBA | C7: Tripulante Ejemplo 05 | D7: LCK PRORROGA | E7: Sebastian Correa | F7: Fiorella Ruiz | G7: Grupo 1 | H7: SI
A8: 9000006 | B8: JSBA | C8: Tripulante Ejemplo 06 | D8: LCK P2 | E8: Karen Santa Cruz | F8: Fiorella Ruiz | G8: Grupo 1 | H8: SI
A9: 9000007 | B9: TCA | C9: Tripulante Ejemplo 07 | D9: LCK P1 | F9: Fiorella Ruiz | G9: Grupo 1 | H9: SI
A10: 9000008 | B10: TCA | C10: Tripulante Ejemplo 08 | D10: LCK PRORROGA | F10: Jefferson Mendez | G10: Grupo 1 | H10: SI
A11: 9000009 | B11: TCA | C11: Tripulante Ejemplo 09 | D11: LCK P1 | E11: Javier Zapata | F11: Jefferson Mendez | G11: Grupo 1 | H11: SI
A12: 9000010 | B12: TCA | C12: Tripulante Ejemplo 10 | D12: LCK P1 | F12: Jefferson Mendez | G12: Grupo 1 | H12: SI
A13: 9000011 | B13: TCA | C13: Tripulante Ejemplo 11 | D13: LCK P2 | F13: Jefferson Mendez | G13: Grupo 1 | H13: SI
A14: 9000012 | B14: TCA | C14: Tripulante Ejemplo 12 | D14: LCK PRORROGA | F14: Sebastian Correa | G14: Grupo 1 | H14: SI
A15: 9000013 | B15: TCA | C15: Tripulante Ejemplo 13 | D15: LCK P2 | E15: Claudia Flores | F15: Sebastian Correa | G15: Grupo 1 | H15: SI
A16: 9000014 | B16: TCA | C16: Tripulante Ejemplo 14 | D16: LCK PRORROGA | E16: Fiorella Ruiz | F16: Sebastian Correa | G16: Grupo 1 | H16: SI
A17: 9000015 | B17: TCA | C17: Tripulante Ejemplo 15 | D17: LCK PRORROGA | E17: Claudia Flores | F17: Sebastian Correa | G17: Grupo 1 | H17: SI
A18: 9000016 | B18: TCA | C18: Tripulante Ejemplo 16 | D18: LCK P1 | F18: Claudia Flores | G18: Grupo 2 | H18: SI
A19: 9000017 | B19: TCB | C19: Tripulante Ejemplo 17 | D19: LCK P2 | F19: Claudia Flores | G19: Grupo 2 | H19: SI
A20: 9000018 | B20: TCA | C20: Tripulante Ejemplo 18 | D20: LCK P1 | F20: Claudia Flores | G20: Grupo 2 | H20: SI
A21: 9000019 | B21: TCA | C21: Tripulante Ejemplo 19 | D21: LCK PRORROGA | E21: Patricia Najar | F21: Javier Zapata | G21: Grupo 2 | H21: SI
A22: 9000020 | B22: TCA | C22: Tripulante Ejemplo 20 | D22: LCK PRORROGA | F22: Javier Zapata | G22: Grupo 2 | H22: SI
A23: 9000021 | B23: JSBA | C23: Tripulante Ejemplo 21 | D23: LCK PRORROGA | E23: Jennifert Acurio | F23: Javier Zapata | G23: Grupo 2 | H23: SI
A24: 9000022 | B24: TCB | C24: Tripulante Ejemplo 22 | D24: LCK P2 | F24: Javier Zapata | G24: Grupo 2 | H24: SI
A25: 9000023 | B25: JSBA | C25: Tripulante Ejemplo 23 | D25: LCK P1 | F25: Jazmin Guerra | G25: Grupo 2 | H25: SI
A26: 9000024 | B26: TCA | C26: Tripulante Ejemplo 24 | D26: LCK P1 | F26: Jazmin Guerra | G26: Grupo 2 | H26: SI
A27: 9000025 | B27: TCA | C27: Tripulante Ejemplo 25 | D27: LCK P2 | E27: Sebastian Correa | F27: Jazmin Guerra | G27: Grupo 2 | H27: SI
A28: 9000026 | B28: TCA | C28: Tripulante Ejemplo 26 | D28: LCK P1 | F28: Jazmin Guerra | G28: Grupo 2 | H28: SI
A29: 9000027 | B29: TCB | C29: Tripulante Ejemplo 27 | D29: LCK PRORROGA | F29: Jennifert Acurio | G29: Grupo 2 | H29: SI
A30: 9000028 | B30: TCA | C30: Tripulante Ejemplo 28 | D30: LCK P1 | E30: Gabriela Ungaro | F30: Jennifert Acurio | G30: Grupo 2 | H30: SI
A31: 9000029 | B31: JSBA | C31: Tripulante Ejemplo 29 | D31: LCK P2 | F31: Jennifert Acurio | G31: Grupo 2 | H31: SI
A32: 9000030 | B32: TCB | C32: Tripulante Ejemplo 30 | D32: LCK PRORROGA | F32: Gabriela Ungaro | G32: Grupo 3 | H32: SI
A33: 9000031 | B33: TCA | C33: Tripulante Ejemplo 31 | D33: LCK P1 | F33: Gabriela Ungaro | G33: Grupo 3 | H33: SI
A34: 9000032 | B34: TCA | C34: Tripulante Ejemplo 32 | D34: LCK P1 | F34: Gabriela Ungaro | G34: Grupo 3 | H34: SI

Sheet Grupos Instructores
A1: Grupo | B1: Instructor
A2: Grupo 1 | B2: Christian Rondon
A3: Grupo 1 | B3: Fiorella Ruiz
A4: Grupo 1 | B4: Jefferson Mendez
A5: Grupo 1 | B5: Sebastian Correa
A6: Grupo 2 | B6: Claudia Flores
A7: Grupo 2 | B7: Javier Zapata
A8: Grupo 2 | B8: Jazmin Guerra
A9: Grupo 2 | B9: Jennifert Acurio
A10: Grupo 3 | B10: Gabriela Ungaro
A11: Grupo 3 | B11: Karen Santa Cruz
A12: Grupo 3 | B12: Patricia Najar
