Workbook

Sheet Pairings
B1: Comenzar asignando vuelos los Jueves y Viernes (porque el SAB es DO)
B2: LCK de ida (porque va OP) y de retorno DGAC o RECA
B4: Pairing ID | C4: FECHA REAL | D4: MES | E4: Day of Week | F4: Flight No | G4: Dep Stn | H4: Arr Stn | I4: STD | J4: STA | K4: DAY | L4: AC Type | M4: HBT | N4: DIA_DUTY | P4: LCK B767
B5: 20 | C5: 01/09/2026 | D5: Sep-2026 | E5: martes | F5: 2480 | G5: LIM | H5: MIA | I5: 00:15:00 | J5: 06:20:00 | K5: NO | L5: 763 | M5: 06:05:00 | N5: 2 | Q5: ="- "&G5&"-"&H5 -> - LIM-MIA | R5: ="- LA "&F5&" ("&LEFT(I5,5)&"-"&LEFT(J5,5)&" hrs)" -> - LA 2480 (00:15-06:20 hrs)
B6: 20 | C6: 02/09/2026 | D6: Sep-2026 | E6: miércoles | F6: 2481 | G6: MIA | H6: LIM | I6: 15:55:00 | J6: 21:40:00 | K6: NO | L6: 763 | M6: 05:45:00 | N6: 3 | O6: =O4 -> 0 | Q6: ="- "&G6&"-"&H6 -> - MIA-LIM | R6: ="- LA "&F6&" ("&LEFT(I6,5)&"-"&LEFT(J6,5)&" hrs)" -> - LA 2481 (15:55-21:40 hrs)
B9: Pairing ID | C9: FECHA REAL | D9: MES | E9: Day of Week | F9: Flight No | G9: Dep Stn | H9: Arr Stn | I9: STD | J9: STA | K9: DAY | L9: AC Type | M9: HBT | N9: DIA_DUTY | P9: LCK B767
B10: 29 | C10: 02/09/2026 | D10: Sep-2026 | E10: miércoles | F10: 2480 | G10: LIM | H10: MIA | I10: 00:15:00 | J10: 06:20:00 | K10: NO | L10: 763 | M10: 06:05:00 | N10: 2 | Q10: ="- "&G10&"-"&H10 -> - LIM-MIA | R10: ="- LA "&F10&" ("&LEFT(I10,5)&"-"&LEFT(J10,5)&" hrs)" -> - LA 2480 (00:15-06:20 hrs)
B11: 29 | C11: 03/09/2026 | D11: Sep-2026 | E11: jueves | F11: 2695 | G11: MIA | H11: LIM | I11: 16:10:00 | J11: 22:00:00 | K11: NO | L11: 763 | M11: 05:50:00 | N11: 3 | O11: =O9 -> 0 | Q11: ="- "&G11&"-"&H11 -> - MIA-LIM | R11: ="- LA "&F11&" ("&LEFT(I11,5)&"-"&LEFT(J11,5)&" hrs)" -> - LA 2695 (16:10-22:00 hrs)
B14: Pairing ID | C14: FECHA REAL | D14: MES | E14: Day of Week | F14: Flight No | G14: Dep Stn | H14: Arr Stn | I14: STD | J14: STA | K14: DAY | L14: AC Type | M14: HBT | N14: DIA_DUTY | P14: LCK B767
B15: 39 | C15: 03/09/2026 | D15: Sep-2026 | E15: jueves | F15: 2480 | G15: LIM | H15: MIA | I15: 00:15:00 | J15: 06:20:00 | K15: NO | L15: 763 | M15: 06:05:00 | N15: 2 | Q15: ="- "&G15&"-"&H15 -> - LIM-MIA | R15: ="- LA "&F15&" ("&LEFT(I15,5)&"-"&LEFT(J15,5)&" hrs)" -> - LA 2480 (00:15-06:20 hrs)
B16: 39 | C16: 04/09/2026 | D16: Sep-2026 | E16: viernes | F16: 2481 | G16: MIA | H16: LIM | I16: 15:55:00 | J16: 21:40:00 | K16: NO | L16: 763 | M16: 05:45:00 | N16: 3 | O16: =O14 -> 0 | Q16: ="- "&G16&"-"&H16 -> - MIA-LIM | R16: ="- LA "&F16&" ("&LEFT(I16,5)&"-"&LEFT(J16,5)&" hrs)" -> - LA 2481 (15:55-21:40 hrs)
B19: Pairing ID | C19: FECHA REAL | D19: MES | E19: Day of Week | F19: Flight No | G19: Dep Stn | H19: Arr Stn | I19: STD | J19: STA | K19: DAY | L19: AC Type | M19: HBT | N19: DIA_DUTY | P19: LCK B767
B20: 44 | C20: 03/09/2026 | D20: Sep-2026 | E20: jueves | F20: 2413 | G20: LIM | H20: SCL | I20: 12:05:00 | J20: 15:45:00 | K20: NO | L20: 763 | M20: 03:40:00 | N20: 1 | Q20: ="- "&G20&"-"&H20 -> - LIM-SCL | R20: ="- LA "&F20&" ("&LEFT(I20,5)&"-"&LEFT(J20,5)&" hrs)" -> - LA 2413 (12:05-15:45 hrs)
B21: 44 | C21: 03/09/2026 | D21: Sep-2026 | E21: jueves | F21: 2412 | G21: SCL | H21: LIM | I21: 17:10:00 | J21: 21:00:00 | K21: NO | L21: 763 | M21: 03:50:00 | N21: 1 | O21: =O19 -> 0 | Q21: ="- "&G21&"-"&H21 -> - SCL-LIM | R21: ="- LA "&F21&" ("&LEFT(I21,5)&"-"&LEFT(J21,5)&" hrs)" -> - LA 2412 (17:10-21:00 hrs)
B24: Pairing ID | C24: FECHA REAL | D24: MES | E24: Day of Week | F24: Flight No | G24: Dep Stn | H24: Arr Stn | I24: STD | J24: STA | K24: DAY | L24: AC Type | M24: HBT | N24: DIA_DUTY | P24: LCK B767
B25: 54 | C25: 04/09/2026 | D25: Sep-2026 | E25: viernes | F25: 2413 | G25: LIM | H25: SCL | I25: 12:05:00 | J25: 15:45:00 | K25: NO | L25: 763 | M25: 03:40:00 | N25: 1 | Q25: ="- "&G25&"-"&H25 -> - LIM-SCL | R25: ="- LA "&F25&" ("&LEFT(I25,5)&"-"&LEFT(J25,5)&" hrs)" -> - LA 2413 (12:05-15:45 hrs)
B26: 54 | C26: 04/09/2026 | D26: Sep-2026 | E26: viernes | F26: 2412 | G26: SCL | H26: LIM | I26: 17:10:00 | J26: 21:00:00 | K26: NO | L26: 763 | M26: 03:50:00 | N26: 1 | O26: =O24 -> 0 | Q26: ="- "&G26&"-"&H26 -> - SCL-LIM | R26: ="- LA "&F26&" ("&LEFT(I26,5)&"-"&LEFT(J26,5)&" hrs)" -> - LA 2412 (17:10-21:00 hrs)
B29: Pairing ID | C29: FECHA REAL | D29: MES | E29: Day of Week | F29: Flight No | G29: Dep Stn | H29: Arr Stn | I29: STD | J29: STA | K29: DAY | L29: AC Type | M29: HBT | N29: DIA_DUTY | P29: LCK B767
B30: 88 | C30: 07/09/2026 | D30: Sep-2026 | E30: lunes | F30: 2694 | G30: LIM | H30: MIA | I30: 13:30:00 | J30: 19:35:00 | K30: NO | L30: 763 | M30: 06:05:00 | N30: 1 | Q30: ="- "&G30&"-"&H30 -> - LIM-MIA | R30: ="- LA "&F30&" ("&LEFT(I30,5)&"-"&LEFT(J30,5)&" hrs)" -> - LA 2694 (13:30-19:35 hrs)
B31: 88 | C31: 09/09/2026 | D31: Sep-2026 | E31: miércoles | F31: 2699 | G31: MIA | H31: LIM | I31: 23:15:00 | J31: 05:00:00 | K31: NO | L31: 763 | M31: 05:45:00 | N31: 2 | O31: =O29 -> 0 | Q31: ="- "&G31&"-"&H31 -> - MIA-LIM | R31: ="- LA "&F31&" ("&LEFT(I31,5)&"-"&LEFT(J31,5)&" hrs)" -> - LA 2699 (23:15-05:00 hrs)
B34: Pairing ID | C34: FECHA REAL | D34: MES | E34: Day of Week | F34: Flight No | G34: Dep Stn | H34: Arr Stn | I34: STD | J34: STA | K34: DAY | L34: AC Type | M34: HBT | N34: DIA_DUTY | P34: LCK B767
B35: 91 | C35: 08/09/2026 | D35: Sep-2026 | E35: martes | F35: 2480 | G35: LIM | H35: MIA | I35: 00:15:00 | J35: 06:20:00 | K35: NO | L35: 763 | M35: 06:05:00 | N35: 2 | Q35: ="- "&G35&"-"&H35 -> - LIM-MIA | R35: ="- LA "&F35&" ("&LEFT(I35,5)&"-"&LEFT(J35,5)&" hrs)" -> - LA 2480 (00:15-06:20 hrs)
B36: 91 | C36: 09/09/2026 | D36: Sep-2026 | E36: miércoles | F36: 2481 | G36: MIA | H36: LIM | I36: 15:55:00 | J36: 21:40:00 | K36: NO | L36: 763 | M36: 05:45:00 | N36: 3 | O36: =O34 -> 0 | Q36: ="- "&G36&"-"&H36 -> - MIA-LIM | R36: ="- LA "&F36&" ("&LEFT(I36,5)&"-"&LEFT(J36,5)&" hrs)" -> - LA 2481 (15:55-21:40 hrs)
B39: Pairing ID | C39: FECHA REAL | D39: MES | E39: Day of Week | F39: Flight No | G39: Dep Stn | H39: Arr Stn | I39: STD | J39: STA | K39: DAY | L39: AC Type | M39: HBT | N39: DIA_DUTY | P39: LCK B767
B40: 100 | C40: 09/09/2026 | D40: Sep-2026 | E40: miércoles | F40: 2480 | G40: LIM | H40: MIA | I40: 00:15:00 | J40: 06:20:00 | K40: NO | L40: 763 | M40: 06:05:00 | N40: 2 | Q40: ="- "&G40&"-"&H40 -> - LIM-MIA | R40: ="- LA "&F40&" ("&LEFT(I40,5)&"-"&LEFT(J40,5)&" hrs)" -> - LA 2480 (00:15-06:20 hrs)
B41: 100 | C41: 10/09/2026 | D41: Sep-2026 | E41: jueves | F41: 2695 | G41: MIA | H41: LIM | I41: 16:10:00 | J41: 22:00:00 | K41: NO | L41: 763 | M41: 05:50:00 | N41: 3 | O41: =O39 -> 0 | Q41: ="- "&G41&"-"&H41 -> - MIA-LIM | R41: ="- LA "&F41&" ("&LEFT(I41,5)&"-"&LEFT(J41,5)&" hrs)" -> - LA 2695 (16:10-22:00 hrs)
B44: Pairing ID | C44: FECHA REAL | D44: MES | E44: Day of Week | F44: Flight No | G44: Dep Stn | H44: Arr Stn | I44: STD | J44: STA | K44: DAY | L44: AC Type | M44: HBT | N44: DIA_DUTY | P44: LCK B767
B45: 110 | C45: 10/09/2026 | D45: Sep-2026 | E45: jueves | F45: 2480 | G45: LIM | H45: MIA | I45: 00:15:00 | J45: 06:20:00 | K45: NO | L45: 763 | M45: 06:05:00 | N45: 2 | Q45: ="- "&G45&"-"&H45 -> - LIM-MIA | R45: ="- LA "&F45&" ("&LEFT(I45,5)&"-"&LEFT(J45,5)&" hrs)" -> - LA 2480 (00:15-06:20 hrs)
B46: 110 | C46: 11/09/2026 | D46: Sep-2026 | E46: viernes | F46: 2481 | G46: MIA | H46: LIM | I46: 15:55:00 | J46: 21:40:00 | K46: NO | L46: 763 | M46: 05:45:00 | N46: 3 | O46: =O44 -> 0 | Q46: ="- "&G46&"-"&H46 -> - MIA-LIM | R46: ="- LA "&F46&" ("&LEFT(I46,5)&"-"&LEFT(J46,5)&" hrs)" -> - LA 2481 (15:55-21:40 hrs)
B49: Pairing ID | C49: FECHA REAL | D49: MES | E49: Day of Week | F49: Flight No | G49: Dep Stn | H49: Arr Stn | I49: STD | J49: STA | K49: DAY | L49: AC Type | M49: HBT | N49: DIA_DUTY | P49: LCK B767
B50: 115 | C50: 10/09/2026 | D50: Sep-2026 | E50: jueves | F50: 2413 | G50: LIM | H50: SCL | I50: 12:05:00 | J50: 15:45:00 | K50: NO | L50: 763 | M50: 03:40:00 | N50: 1 | Q50: ="- "&G50&"-"&H50 -> - LIM-SCL | R50: ="- LA "&F50&" ("&LEFT(I50,5)&"-"&LEFT(J50,5)&" hrs)" -> - LA 2413 (12:05-15:45 hrs)
B51: 115 | C51: 10/09/2026 | D51: Sep-2026 | E51: jueves | F51: 2412 | G51: SCL | H51: LIM | I51: 17:10:00 | J51: 21:00:00 | K51: NO | L51: 763 | M51: 03:50:00 | N51: 1 | O51: =O49 -> 0 | Q51: ="- "&G51&"-"&H51 -> - SCL-LIM | R51: ="- LA "&F51&" ("&LEFT(I51,5)&"-"&LEFT(J51,5)&" hrs)" -> - LA 2412 (17:10-21:00 hrs)
B54: Pairing ID | C54: FECHA REAL | D54: MES | E54: Day of Week | F54: Flight No | G54: Dep Stn | H54: Arr Stn | I54: STD | J54: STA | K54: DAY | L54: AC Type | M54: HBT | N54: DIA_DUTY | P54: LCK B767
B55: 125 | C55: 11/09/2026 | D55: Sep-2026 | E55: viernes | F55: 2413 | G55: LIM | H55: SCL | I55: 12:05:00 | J55: 15:45:00 | K55: NO | L55: 763 | M55: 03:40:00 | N55: 1 | Q55: ="- "&G55&"-"&H55 -> - LIM-SCL | R55: ="- LA "&F55&" ("&LEFT(I55,5)&"-"&LEFT(J55,5)&" hrs)" -> - LA 2413 (12:05-15:45 hrs)
B56: 125 | C56: 11/09/2026 | D56: Sep-2026 | E56: viernes | F56: 2412 | G56: SCL | H56: LIM | I56: 17:10:00 | J56: 21:00:00 | K56: NO | L56: 763 | M56: 03:50:00 | N56: 1 | O56: =O54 -> 0 | Q56: ="- "&G56&"-"&H56 -> - SCL-LIM | R56: ="- LA "&F56&" ("&LEFT(I56,5)&"-"&LEFT(J56,5)&" hrs)" -> - LA 2412 (17:10-21:00 hrs)
B59: Pairing ID | C59: FECHA REAL | D59: MES | E59: Day of Week | F59: Flight No | G59: Dep Stn | H59: Arr Stn | I59: STD | J59: STA | K59: DAY | L59: AC Type | M59: HBT | N59: DIA_DUTY | P59: LCK B767
B60: 159 | C60: 14/09/2026 | D60: Sep-2026 | E60: lunes | F60: 2694 | G60: LIM | H60: MIA | I60: 13:30:00 | J60: 19:35:00 | K60: NO | L60: 763 | M60: 06:05:00 | N60: 1 | Q60: ="- "&G60&"-"&H60 -> - LIM-MIA | R60: ="- LA "&F60&" ("&LEFT(I60,5)&"-"&LEFT(J60,5)&" hrs)" -> - LA 2694 (13:30-19:35 hrs)
B61: 159 | C61: 16/09/2026 | D61: Sep-2026 | E61: miércoles | F61: 2699 | G61: MIA | H61: LIM | I61: 23:15:00 | J61: 05:00:00 | K61: NO | L61: 763 | M61: 05:45:00 | N61: 2 | O61: =O59 -> 0 | Q61: ="- "&G61&"-"&H61 -> - MIA-LIM | R61: ="- LA "&F61&" ("&LEFT(I61,5)&"-"&LEFT(J61,5)&" hrs)" -> - LA 2699 (23:15-05:00 hrs)
B64: Pairing ID | C64: FECHA REAL | D64: MES | E64: Day of Week | F64: Flight No | G64: Dep Stn | H64: Arr Stn | I64: STD | J64: STA | K64: DAY | L64: AC Type | M64: HBT | N64: DIA_DUTY | P64: LCK B767
B65: 162 | C65: 15/09/2026 | D65: Sep-2026 | E65: martes | F65: 2480 | G65: LIM | H65: MIA | I65: 00:15:00 | J65: 06:20:00 | K65: NO | L65: 763 | M65: 06:05:00 | N65: 2 | Q65: ="- "&G65&"-"&H65 -> - LIM-MIA | R65: ="- LA "&F65&" ("&LEFT(I65,5)&"-"&LEFT(J65,5)&" hrs)" -> - LA 2480 (00:15-06:20 hrs)
...

Sheet Resumen
A1: Pairing ID | B1: Fecha Inicio | C1: Día Sem | D1: Vuelo | E1: Ruta | F1: Instructor | G1: Actividad | H1: Inicio | I1: Fin
A2: =Pairings!B5 -> 20 | B2: =Pairings!C5 -> 01/09/2026 | C2: =Pairings!D5 -> Sep-2026 | D2: =Pairings!F5&"/"&Pairings!F6 -> 2480/2481 | E2: =Pairings!G5&"-"&Pairings!H5&"-"&Pairings!G5 -> LIM-MIA-LIM | F2: =Pairings!O4 -> 0 | G2: =Pairings!P4 -> LCK B767 | H2: =Pairings!C5 -> 01/09/2026 | I2: =Pairings!C6 -> 02/09/2026
A3: =Pairings!B10 -> 29 | B3: =Pairings!C10 -> 02/09/2026 | C3: =Pairings!D10 -> Sep-2026 | D3: =Pairings!F10&"/"&Pairings!F11 -> 2480/2695 | E3: =Pairings!G10&"-"&Pairings!H10&"-"&Pairings!G10 -> LIM-MIA-LIM | F3: =Pairings!O9 -> 0 | G3: =Pairings!P9 -> LCK B767 | H3: =Pairings!C10 -> 02/09/2026 | I3: =Pairings!C11 -> 03/09/2026
A4: =Pairings!B15 -> 39 | B4: =Pairings!C15 -> 03/09/2026 | C4: =Pairings!D15 -> Sep-2026 | D4: =Pairings!F15&"/"&Pairings!F16 -> 2480/2481 | E4: =Pairings!G15&"-"&Pairings!H15&"-"&Pairings!G15 -> LIM-MIA-LIM | F4: =Pairings!O14 -> 0 | G4: =Pairings!P14 -> LCK B767 | H4: =Pairings!C15 -> 03/09/2026 | I4: =Pairings!C16 -> 04/09/2026
A5: =Pairings!B20 -> 44 | B5: =Pairings!C20 -> 03/09/2026 | C5: =Pairings!D20 -> Sep-2026 | D5: =Pairings!F20&"/"&Pairings!F21 -> 2413/2412 | E5: =Pairings!G20&"-"&Pairings!H20&"-"&Pairings!G20 -> LIM-SCL-LIM | F5: =Pairings!O19 -> 0 | G5: =Pairings!P19 -> LCK B767 | H5: =Pairings!C20 -> 03/09/2026 | I5: =Pairings!C21 -> 03/09/2026
A6: =Pairings!B25 -> 54 | B6: =Pairings!C25 -> 04/09/2026 | C6: =Pairings!D25 -> Sep-2026 | D6: =Pairings!F25&"/"&Pairings!F26 -> 2413/2412 | E6: =Pairings!G25&"-"&Pairings!H25&"-"&Pairings!G25 -> LIM-SCL-LIM | F6: =Pairings!O24 -> 0 | G6: =Pairings!P24 -> LCK B767 | H6: =Pairings!C25 -> 04/09/2026 | I6: =Pairings!C26 -> 04/09/2026
A7: =Pairings!B30 -> 88 | B7: =Pairings!C30 -> 07/09/2026 | C7: =Pairings!D30 -> Sep-2026 | D7: =Pairings!F30&"/"&Pairings!F31 -> 2694/2699 | E7: =Pairings!G30&"-"&Pairings!H30&"-"&Pairings!G30 -> LIM-MIA-LIM | F7: =Pairings!O29 -> 0 | G7: =Pairings!P29 -> LCK B767 | H7: =Pairings!C30 -> 07/09/2026 | I7: =Pairings!C31 -> 09/09/2026
A8: =Pairings!B35 -> 91 | B8: =Pairings!C35 -> 08/09/2026 | C8: =Pairings!D35 -> Sep-2026 | D8: =Pairings!F35&"/"&Pairings!F36 -> 2480/2481 | E8: =Pairings!G35&"-"&Pairings!H35&"-"&Pairings!G35 -> LIM-MIA-LIM | F8: =Pairings!O34 -> 0 | G8: =Pairings!P34 -> LCK B767 | H8: =Pairings!C35 -> 08/09/2026 | I8: =Pairings!C36 -> 09/09/2026
A9: =Pairings!B40 -> 100 | B9: =Pairings!C40 -> 09/09/2026 | C9: =Pairings!D40 -> Sep-2026 | D9: =Pairings!F40&"/"&Pairings!F41 -> 2480/2695 | E9: =Pairings!G40&"-"&Pairings!H40&"-"&Pairings!G40 -> LIM-MIA-LIM | F9: =Pairings!O39 -> 0 | G9: =Pairings!P39 -> LCK B767 | H9: =Pairings!C40 -> 09/09/2026 | I9: =Pairings!C41 -> 10/09/2026
A10: =Pairings!B45 -> 110 | B10: =Pairings!C45 -> 10/09/2026 | C10: =Pairings!D45 -> Sep-2026 | D10: =Pairings!F45&"/"&Pairings!F46 -> 2480/2481 | E10: =Pairings!G45&"-"&Pairings!H45&"-"&Pairings!G45 -> LIM-MIA-LIM | F10: =Pairings!O44 -> 0 | G10: =Pairings!P44 -> LCK B767 | H10: =Pairings!C45 -> 10/09/2026 | I10: =Pairings!C46 -> 11/09/2026
A11: =Pairings!B50 -> 115 | B11: =Pairings!C50 -> 10/09/2026 | C11: =Pairings!D50 -> Sep-2026 | D11: =Pairings!F50&"/"&Pairings!F51 -> 2413/2412 | E11: =Pairings!G50&"-"&Pairings!H50&"-"&Pairings!G50 -> LIM-SCL-LIM | F11: =Pairings!O49 -> 0 | G11: =Pairings!P49 -> LCK B767 | H11: =Pairings!C50 -> 10/09/2026 | I11: =Pairings!C51 -> 10/09/2026
A12: =Pairings!B55 -> 125 | B12: =Pairings!C55 -> 11/09/2026 | C12: =Pairings!D55 -> Sep-2026 | D12: =Pairings!F55&"/"&Pairings!F56 -> 2413/2412 | E12: =Pairings!G55&"-"&Pairings!H55&"-"&Pairings!G55 -> LIM-SCL-LIM | F12: =Pairings!O54 -> 0 | G12: =Pairings!P54 -> LCK B767 | H12: =Pairings!C55 -> 11/09/2026 | I12: =Pairings!C56 -> 11/09/2026
A13: =Pairings!B60 -> 159 | B13: =Pairings!C60 -> 14/09/2026 | C13: =Pairings!D60 -> Sep-2026 | D13: =Pairings!F60&"/"&Pairings!F61 -> 2694/2699 | E13: =Pairings!G60&"-"&Pairings!H60&"-"&Pairings!G60 -> LIM-MIA-LIM | F13: =Pairings!O59 -> 0 | G13: =Pairings!P59 -> LCK B767 | H13: =Pairings!C60 -> 14/09/2026 | I13: =Pairings!C61 -> 16/09/2026
A14: =Pairings!B65 -> 162 | B14: =Pairings!C65 -> 15/09/2026 | C14: =Pairings!D65 -> Sep-2026 | D14: =Pairings!F65&"/"&Pairings!F66 -> 2480/2481 | E14: =Pairings!G65&"-"&Pairings!H65&"-"&Pairings!G65 -> LIM-MIA-LIM | F14: =Pairings!O64 -> 0 | G14: =Pairings!P64 -> LCK B767 | H14: =Pairings!C65 -> 15/09/2026 | I14: =Pairings!C66 -> 16/09/2026
A15: =Pairings!B70 -> 171 | B15: =Pairings!C70 -> 16/09/2026 | C15: =Pairings!D70 -> Sep-2026 | D15: =Pairings!F70&"/"&Pairings!F71 -> 2480/2695 | E15: =Pairings!G70&"-"&Pairings!H70&"-"&Pairings!G70 -> LIM-MIA-LIM | F15: =Pairings!O69 -> 0 | G15: =Pairings!P69 -> LCK B767 | H15: =Pairings!C70 -> 16/09/2026 | I15: =Pairings!C71 -> 17/09/2026
A16: =Pairings!B75 -> 181 | B16: =Pairings!C75 -> 17/09/2026 | C16: =Pairings!D75 -> Sep-2026 | D16: =Pairings!F75&"/"&Pairings!F76 -> 2480/2481 | E16: =Pairings!G75&"-"&Pairings!H75&"-"&Pairings!G75 -> LIM-MIA-LIM | F16: =Pairings!O74 -> 0 | G16: =Pairings!P74 -> LCK B767 | H16: =Pairings!C75 -> 17/09/2026 | I16: =Pairings!C76 -> 18/09/2026
A17: =Pairings!B80 -> 186 | B17: =Pairings!C80 -> 17/09/2026 | C17: =Pairings!D80 -> Sep-2026 | D17: =Pairings!F80&"/"&Pairings!F81 -> 2413/2412 | E17: =Pairings!G80&"-"&Pairings!H80&"-"&Pairings!G80 -> LIM-SCL-LIM | F17: =Pairings!O79 -> 0 | G17: =Pairings!P79 -> LCK B767 | H17: =Pairings!C80 -> 17/09/2026 | I17: =Pairings!C81 -> 17/09/2026
A18: =Pairings!B85 -> 196 | B18: =Pairings!C85 -> 18/09/2026 | C18: =Pairings!D85 -> Sep-2026 | D18: =Pairings!F85&"/"&Pairings!F86 -> 2413/2412 | E18: =Pairings!G85&"-"&Pairings!H85&"-"&Pairings!G85 -> LIM-SCL-LIM | F18: =Pairings!O84 -> 0 | G18: =Pairings!P84 -> LCK B767 | H18: =Pairings!C85 -> 18/09/2026 | I18: =Pairings!C86 -> 18/09/2026
A19: =Pairings!B90 -> 230 | B19: =Pairings!C90 -> 21/09/2026 | C19: =Pairings!D90 -> Sep-2026 | D19: =Pairings!F90&"/"&Pairings!F91 -> 2694/2699 | E19: =Pairings!G90&"-"&Pairings!H90&"-"&Pairings!G90 -> LIM-MIA-LIM | F19: =Pairings!O89 -> 0 | G19: =Pairings!P89 -> LCK B767 | H19: =Pairings!C90 -> 21/09/2026 | I19: =Pairings!C91 -> 23/09/2026
A20: =Pairings!B95 -> 233 | B20: =Pairings!C95 -> 22/09/2026 | C20: =Pairings!D95 -> Sep-2026 | D20: =Pairings!F95&"/"&Pairings!F96 -> 2480/2481 | E20: =Pairings!G95&"-"&Pairings!H95&"-"&Pairings!G95 -> LIM-MIA-LIM | F20: =Pairings!O94 -> 0 | G20: =Pairings!P94 -> LCK B767 | H20: =Pairings!C95 -> 22/09/2026 | I20: =Pairings!C96 -> 23/09/2026
A21: =Pairings!B100 -> 242 | B21: =Pairings!C100 -> 23/09/2026 | C21: =Pairings!D100 -> Sep-2026 | D21: =Pairings!F100&"/"&Pairings!F101 -> 2480/2695 | E21: =Pairings!G100&"-"&Pairings!H100&"-"&Pairings!G100 -> LIM-MIA-LIM | F21: =Pairings!O99 -> 0 | G21: =Pairings!P99 -> LCK B767 | H21: =Pairings!C100 -> 23/09/2026 | I21: =Pairings!C101 -> 24/09/2026
A22: =Pairings!B105 -> 252 | B22: =Pairings!C105 -> 24/09/2026 | C22: =Pairings!D105 -> Sep-2026 | D22: =Pairings!F105&"/"&Pairings!F106 -> 2480/2481 | E22: =Pairings!G105&"-"&Pairings!H105&"-"&Pairings!G105 -> LIM-MIA-LIM | F22: =Pairings!O104 -> 0 | G22: =Pairings!P104 -> LCK B767 | H22: =Pairings!C105 -> 24/09/2026 | I22: =Pairings!C106 -> 25/09/2026
A23: =Pairings!B110 -> 257 | B23: =Pairings!C110 -> 24/09/2026 | C23: =Pairings!D110 -> Sep-2026 | D23: =Pairings!F110&"/"&Pairings!F111 -> 2413/2412 | E23: =Pairings!G110&"-"&Pairings!H110&"-"&Pairings!G110 -> LIM-SCL-LIM | F23: =Pairings!O109 -> 0 | G23: =Pairings!P109 -> LCK B767 | H23: =Pairings!C110 -> 24/09/2026 | I23: =Pairings!C111 -> 24/09/2026
A24: =Pairings!B115 -> 267 | B24: =Pairings!C115 -> 25/09/2026 | C24: =Pairings!D115 -> Sep-2026 | D24: =Pairings!F115&"/"&Pairings!F116 -> 2413/2412 | E24: =Pairings!G115&"-"&Pairings!H115&"-"&Pairings!G115 -> LIM-SCL-LIM | F24: =Pairings!O114 -> 0 | G24: =Pairings!P114 -> LCK B767 | H24: =Pairings!C115 -> 25/09/2026 | I24: =Pairings!C116 -> 25/09/2026
A25: =Pairings!B120 -> 297 | B25: =Pairings!C120 -> 28/09/2026 | C25: =Pairings!D120 -> Sep-2026 | D25: =Pairings!F120&"/"&Pairings!F121 -> 2698/2699 | E25: =Pairings!G120&"-"&Pairings!H120&"-"&Pairings!G120 -> LIM-MIA-LIM | F25: =Pairings!O119 -> 0 | G25: =Pairings!P119 -> LCK B767 | H25: =Pairings!C120 -> 28/09/2026 | I25: =Pairings!C121 -> 30/09/2026
A26: =Pairings!B125 -> 304 | B26: =Pairings!C125 -> 29/09/2026 | C26: =Pairings!D125 -> Sep-2026 | D26: =Pairings!F125&"/"&Pairings!F126 -> 2480/2481 | E26: =Pairings!G125&"-"&Pairings!H125&"-"&Pairings!G125 -> LIM-MIA-LIM | F26: =Pairings!O124 -> 0 | G26: =Pairings!P124 -> LCK B767 | H26: =Pairings!C125 -> 29/09/2026 | I26: =Pairings!C126 -> 30/09/2026
A27: =Pairings!B130 -> 313 | B27: =Pairings!C130 -> 30/09/2026 | C27: =Pairings!D130 -> Sep-2026 | D27: =Pairings!F130&"/"&Pairings!F131 -> 2480/2695 | E27: =Pairings!G130&"-"&Pairings!H130&"-"&Pairings!G130 -> LIM-MIA-LIM | F27: =Pairings!O129 -> 0 | G27: =Pairings!P129 -> LCK B767 | H27: =Pairings!C130 -> 30/09/2026 | I27: =Pairings!C131 -> 01/10/2026
